Workbook

Sheet ЯНВАРЬ
A1: ИМЯ | B1: 46023 | C1: 1 | D1: 2 | E1: 3 | F1: 4 | G1: 5 | H1: 6 | I1: 7 | J1: 8 | K1: 9 | L1: 10 | M1: 11 | N1: 12 | O1: 13 | P1: 14 | Q1: 15 | R1: 16 | S1: 17 | T1: 18 | U1: 19 | V1: 20 | W1: 21 | X1: 22 | Y1: 23 | Z1: 24 | AA1: 25 | AB1: 26 | AC1: 27 | AD1: 28 | AE1: 29 | AF1: 30 | AG1: 31 | AH1: Ставка | AL1: % | AO1: ИТОГО СМЕН | AU1: РАСЧЕТ ЗП | CU1: Переплата
A2: ИМЯ | B2: 46053.999 | C2: чт | D2: пт | E2: сб | F2: вс | G2: пн | H2: вт | I2: ср | J2: чт | K2: пт | L2: сб | M2: вс | N2: пн | O2: вт | P2: ср | Q2: чт | R2: пт | S2: сб | T2: вс | U2: пн | V2: вт | W2: ср | X2: чт | Y2: пт | Z2: сб | AA2: вс | AB2: пн | AC2: вт | AD2: ср | AE2: чт | AF2: пт | AG2: сб | AH2: ОСН | AJ2: ДОП | AL2: Р | AM2: К | AN2: О | AO2: ОСН. | AQ2: ДОП. | AS2: ОБЩ | AU2: ОКЛАД | AY2: Ремонт | BC2: Косметика | BG2: Обувь | BK2: Аксессуары | BO2: Ключи | BS2: Тапки | BW2: Цех | CA2: Бонус | CE2: ИТОГО | CI2: Удержание | CM2: Аванс | CQ2: К выплате
A3: Вера 0102 | G3: Ц | H3: Ц | K3: Ц | L3: Ц | O3: Ц | P3: Ц | S3: Ц | T3: Ц | W3: Ц | X3: Ц | AA3: Ц | AB3: Ц | AE3: Ц | AF3: Ц | AH3: 3500 | AJ3: 4000 | AL3: 0 | AM3: 0 | AN3: 0 | AO3: =AS3-AQ3 -> 14 | AQ3: =IF(AS3>15, AS3-15, 0) -> 0 | AS3: =COUNTIF(C3:AG3, "М")+COUNTIF(C3:AG3, "Ц")+COUNTIF(C3:AG3, "П")+COUNTIF(C3:AG3, "Ох")+COUNTIF(C3:AG3, "Оз")+COUNTIF(C3:AG3, "А")+COUNTIF(C3:AG3, "Р")+(COUNTIF(C3:AG3, "05М")/2)+(COUNTIF(C3:AG3, "05Ц")/2)+(COUNTIF(C3:AG3, "05П")/2)+(COUNTIF(C3:AG3, "05Ох")/2)+(COUNTIF(C3:AG3, "05Оз")/2)+(COUNTIF(C3:AG3, "05А")/2)+(COUNTIF(C3:AG3, "05Р")/2) -> 14 | AU3: =AO3*AH3+AQ3*AJ3 -> 49000 | AY3: {=SUMPRODUCT( (RIGHT([1]Запрос1!$D$2:$D$43198,4)=RIGHT(A3,4))* ([1]Запрос1!$A$2:$A$43198>=$B$1)* ([1]Запрос1!$A$2:$A$43198<=$B$2)* [1]Запрос1!$F$2:$F$43198)*AL3} -> 0 | BC3: {=SUMPRODUCT( (RIGHT([2]Запрос1!$E$2:$E$2465,4) = RIGHT(A3,4)) * ([2]Запрос1!$A$2:$A$2465 >= $B$1) * ([2]Запрос1!$A$2:$A$2465 <= $B$2) * [2]Запрос1!$I$2:$I$2465 )*AM3} -> 0 | BG3: {=SUMPRODUCT( --(RIGHT([3]Запрос1!$C$2:$C$5232,4) = RIGHT(A3,4)), --([3]Запрос1!$E$2:$E$5232 >= $B$1), --([3]Запрос1!$E$2:$E$5232 <= $B$2) )*AN3} -> 0 | BK3: {=SUMPRODUCT( (RIGHT([4]Запрос1!$E$2:$E$5389,4)=RIGHT(A3,4))* ([4]Запрос1!$A$2:$A$5389>=$B$1)* ([4]Запрос1!$A$2:$A$5389<=$B$2)* [4]Запрос1!$J$2:$J$5389 )*0.01} -> 0 | BO3: 0 | BW3: =IF(AND(C3="Ц",COUNTIF($C$3:$C$21,"Ц")=1),1000,0) + IF(AND(D3="Ц",COUNTIF($D$3:$D$21,"Ц")=1),1000,0) + IF(AND(E3="Ц",COUNTIF($E$3:$E$21,"Ц")=1),1000,0) + IF(AND(F3="Ц",COUNTIF($F$3:$F$21,"Ц")=1),1000,0) + IF(AND(G3="Ц",COUNTIF($G$3:$G$21,"Ц")=1),1000,0) + IF(AND(H3="Ц",COUNTIF($H$3:$H$21,"Ц")=1),1000,0) + IF(AND(I3="Ц",COUNTIF($I$3:$I$21,"Ц")=1),1000,0) + IF(AND(J3="Ц",COUNTIF($J$3:$J$21,"Ц")=1),1000,0) + IF(AND(K3="Ц",COUNTIF($K$3:$K$21,"Ц")=1),1000,0) + IF(AND(L3="Ц",COUNTIF($L$3:$L$21,"Ц")=1),1000,0) + IF(AND(M3="Ц",COUNTIF($M$3:$M$21,"Ц")=1),1000,0) + IF(AND(N3="Ц",COUNTIF($N$3:$N$21,"Ц")=1),1000,0) + IF(AND(O3="Ц",COUNTIF($O$3:$O$21,"Ц")=1),1000,0) + IF(AND(P3="Ц",COUNTIF($P$3:$P$21,"Ц")=1),1000,0) + IF(AND(Q3="Ц",COUNTIF($Q$3:$Q$21,"Ц")=1),1000,0) + IF(AND(R3="Ц",COUNTIF($R$3:$R$21,"Ц")=1),1000,0) + IF(AND(S3="Ц",COUNTIF($S$3:$S$21,"Ц")=1),1000,0) + IF(AND(T3="Ц",COUNTIF($T$3:$T$21,"Ц")=1),1000,0) + IF(AND(U3="Ц",COUNTIF($U$3:$U$21,"Ц")=1),1000,0) + IF(AND(V3="Ц",COUNTIF($V$3:$V$21,"Ц")=1),1000,0) + IF(AND(W3="Ц",COUNTIF($W$3:$W$21,"Ц")=1),1000,0) + IF(AND(X3="Ц",COUNTIF($X$3:$X$21,"Ц")=1),1000,0) + IF(AND(Y3="Ц",COUNTIF($Y$3:$Y$21,"Ц")=1),1000,0) + IF(AND(Z3="Ц",COUNTIF($Z$3:$Z$21,"Ц")=1),1000,0) + IF(AND(AA3="Ц",COUNTIF($AA$3:$AA$21,"Ц")=1),1000,0) + IF(AND(AB3="Ц",COUNTIF($AB$3:$AB$21,"Ц")=1),1000,0) + IF(AND(AC3="Ц",COUNTIF($AC$3:$AC$21,"Ц")=1),1000,0) + IF(AND(AD3="Ц",COUNTIF($AD$3:$AD$21,"Ц")=1),1000,0) + IF(AND(AE3="Ц",COUNTIF($AE$3:$AE$21,"Ц")=1),1000,0) + IF(AND(AF3="Ц",COUNTIF($AF$3:$AF$21,"Ц")=1),1000,0) + IF(AND(AG3="Ц",COUNTIF($AG$3:$AG$21,"Ц")=1),1000,0) -> 14000 | CE3: =SUM(AU3:CD3) -> 63000 | CQ3: =(AU3+SUM(AY3:CD3))-SUM(CI3:CP3) -> 63000 | CU3: =AJ3*AQ3-AH3*AQ3 -> 0
A4: Арина 7272 | I4: Ц | J4: Ц | M4: Ц | N4: Ц | Q4: Ц | R4: Ц | U4: Ц | V4: Ц | Y4: Ц | Z4: Ц | AC4: Ц | AD4: Ц | AG4: Ц | AH4: 3500 | AJ4: 4000 | AL4: 0 | AM4: 0 | AN4: 0 | AO4: =AS4-AQ4 -> 13 | AQ4: =IF(AS4>15, AS4-15, 0) -> 0 | AS4: =COUNTIF(C4:AG4, "М")+COUNTIF(C4:AG4, "Ц")+COUNTIF(C4:AG4, "П")+COUNTIF(C4:AG4, "Ох")+COUNTIF(C4:AG4, "Оз")+COUNTIF(C4:AG4, "А")+COUNTIF(C4:AG4, "Р")+(COUNTIF(C4:AG4, "05М")/2)+(COUNTIF(C4:AG4, "05Ц")/2)+(COUNTIF(C4:AG4, "05П")/2)+(COUNTIF(C4:AG4, "05Ох")/2)+(COUNTIF(C4:AG4, "05Оз")/2)+(COUNTIF(C4:AG4, "05А")/2)+(COUNTIF(C4:AG4, "05Р")/2) -> 13 | AU4: =AO4*AH4+AQ4*AJ4 -> 45500 | AY4: {=SUMPRODUCT( (RIGHT([1]Запрос1!$D$2:$D$43198,4)=RIGHT(A4,4))* ([1]Запрос1!$A$2:$A$43198>=$B$1)* ([1]Запрос1!$A$2:$A$43198<=$B$2)* [1]Запрос1!$F$2:$F$43198)*AL4} -> 0 | BC4: {=SUMPRODUCT( (RIGHT([2]Запрос1!$E$2:$E$2465,4) = RIGHT(A4,4)) * ([2]Запрос1!$A$2:$A$2465 >= $B$1) * ([2]Запрос1!$A$2:$A$2465 <= $B$2) * [2]Запрос1!$I$2:$I$2465 )*AM4} -> 0 | BG4: {=SUMPRODUCT( --(RIGHT([3]Запрос1!$C$2:$C$5232,4) = RIGHT(A4,4)), --([3]Запрос1!$E$2:$E$5232 >= $B$1), --([3]Запрос1!$E$2:$E$5232 <= $B$2) )*AN4} -> 0 | BK4: {=SUMPRODUCT( (RIGHT([4]Запрос1!$E$2:$E$5389,4)=RIGHT(A4,4))* ([4]Запрос1!$A$2:$A$5389>=$B$1)* ([4]Запрос1!$A$2:$A$5389<=$B$2)* [4]Запрос1!$J$2:$J$5389 )*0.01} -> 0 | BO4: {=SUMPRODUCT( (RIGHT([5]Запрос1!$E$2:$E$5270,4) = RIGHT(A4,4)) * ([5]Запрос1!$A$2:$A$5270 >= $B$1) * ([5]Запрос1!$A$2:$A$5270 <= $B$2) * [5]Запрос1!$I$2:$I$5270 )*0.25} -> 0 | BW4: =IF(AND(C4="Ц",COUNTIF($C$3:$C$21,"Ц")=1),1000,0) + IF(AND(D4="Ц",COUNTIF($D$3:$D$21,"Ц")=1),1000,0) + IF(AND(E4="Ц",COUNTIF($E$3:$E$21,"Ц")=1),1000,0) + IF(AND(F4="Ц",COUNTIF($F$3:$F$21,"Ц")=1),1000,0) + IF(AND(G4="Ц",COUNTIF($G$3:$G$21,"Ц")=1),1000,0) + IF(AND(H4="Ц",COUNTIF($H$3:$H$21,"Ц")=1),1000,0) + IF(AND(I4="Ц",COUNTIF($I$3:$I$21,"Ц")=1),1000,0) + IF(AND(J4="Ц",COUNTIF($J$3:$J$21,"Ц")=1),1000,0) + IF(AND(K4="Ц",COUNTIF($K$3:$K$21,"Ц")=1),1000,0) + IF(AND(L4="Ц",COUNTIF($L$3:$L$21,"Ц")=1),1000,0) + IF(AND(M4="Ц",COUNTIF($M$3:$M$21,"Ц")=1),1000,0) + IF(AND(N4="Ц",COUNTIF($N$3:$N$21,"Ц")=1),1000,0) + IF(AND(O4="Ц",COUNTIF($O$3:$O$21,"Ц")=1),1000,0) + IF(AND(P4="Ц",COUNTIF($P$3:$P$21,"Ц")=1),1000,0) + IF(AND(Q4="Ц",COUNTIF($Q$3:$Q$21,"Ц")=1),1000,0) + IF(AND(R4="Ц",COUNTIF($R$3:$R$21,"Ц")=1),1000,0) + IF(AND(S4="Ц",COUNTIF($S$3:$S$21,"Ц")=1),1000,0) + IF(AND(T4="Ц",COUNTIF($T$3:$T$21,"Ц")=1),1000,0) + IF(AND(U4="Ц",COUNTIF($U$3:$U$21,"Ц")=1),1000,0) + IF(AND(V4="Ц",COUNTIF($V$3:$V$21,"Ц")=1),1000,0) + IF(AND(W4="Ц",COUNTIF($W$3:$W$21,"Ц")=1),1000,0) + IF(AND(X4="Ц",COUNTIF($X$3:$X$21,"Ц")=1),1000,0) + IF(AND(Y4="Ц",COUNTIF($Y$3:$Y$21,"Ц")=1),1000,0) + IF(AND(Z4="Ц",COUNTIF($Z$3:$Z$21,"Ц")=1),1000,0) + IF(AND(AA4="Ц",COUNTIF($AA$3:$AA$21,"Ц")=1),1000,0) + IF(AND(AB4="Ц",COUNTIF($AB$3:$AB$21,"Ц")=1),1000,0) + IF(AND(AC4="Ц",COUNTIF($AC$3:$AC$21,"Ц")=1),1000,0) + IF(AND(AD4="Ц",COUNTIF($AD$3:$AD$21,"Ц")=1),1000,0) + IF(AND(AE4="Ц",COUNTIF($AE$3:$AE$21,"Ц")=1),1000,0) + IF(AND(AF4="Ц",COUNTIF($AF$3:$AF$21,"Ц")=1),1000,0) + IF(AND(AG4="Ц",COUNTIF($AG$3:$AG$21,"Ц")=1),1000,0) -> 13000 | CE4: =SUM(AU4:CD4) -> 58500 | CQ4: =(AU4+SUM(AY4:CD4))-SUM(CI4:CP4) -> 58500 | CU4: =AJ4*AQ4-AH4*AQ4 -> 0
A5: Александр 1505 | G5: Ох | H5: Ох | I5: Ох | M5: Ох | N5: Ох | O5: Ох | S5: Ох | T5: Ох | U5: Ох | Y5: Ох | Z5: Ох | AA5: Ох | AE5: Ох | AF5: Ох | AH5: 3000 | AJ5: 3500 | AL5: 0.01 | AM5: 0.05 | AN5: 1000 | AO5: =AS5-AQ5 -> 14 | AQ5: =IF(AS5>15, AS5-15, 0) -> 0 | AS5: =COUNTIF(C5:AG5, "М")+COUNTIF(C5:AG5, "Ц")+COUNTIF(C5:AG5, "П")+COUNTIF(C5:AG5, "Ох")+COUNTIF(C5:AG5, "Оз")+COUNTIF(C5:AG5, "А")+COUNTIF(C5:AG5, "Р")+(COUNTIF(C5:AG5, "05М")/2)+(COUNTIF(C5:AG5, "05Ц")/2)+(COUNTIF(C5:AG5, "05П")/2)+(COUNTIF(C5:AG5, "05Ох")/2)+(COUNTIF(C5:AG5, "05Оз")/2)+(COUNTIF(C5:AG5, "05А")/2)+(COUNTIF(C5:AG5, "05Р")/2) -> 14 | AU5: =AO5*AH5+AQ5*AJ5 -> 42000 | AY5: {=SUMPRODUCT( (RIGHT([1]Запрос1!$D$2:$D$43198,4)=RIGHT(A5,4))* ([1]Запрос1!$A$2:$A$43198>=$B$1)* ([1]Запрос1!$A$2:$A$43198<=$B$2)* [1]Запрос1!$F$2:$F$43198)*AL5} -> 1660.47 | BC5: {=SUMPRODUCT( (RIGHT([2]Запрос1!$E$2:$E$2465,4) = RIGHT(A5,4)) * ([2]Запрос1!$A$2:$A$2465 >= $B$1) * ([2]Запрос1!$A$2:$A$2465 <= $B$2) * [2]Запрос1!$I$2:$I$2465 )*AM5} -> 1959.5 | BG5: {=SUMPRODUCT( --(RIGHT([3]Запрос1!$C$2:$C$5232,4) = RIGHT(A5,4)), --([3]Запрос1!$E$2:$E$5232 >= $B$1), --([3]Запрос1!$E$2:$E$5232 <= $B$2) )*AN5} -> 6000 | BK5: {=SUMPRODUCT( (RIGHT([4]Запрос1!$E$2:$E$5389,4)=RIGHT(A5,4))* ([4]Запрос1!$A$2:$A$5389>=$B$1)* ([4]Запрос1!$A$2:$A$5389<=$B$2)* [4]Запрос1!$J$2:$J$5389 )*0.01} -> 0 | BO5: {=SUMPRODUCT( (RIGHT([5]Запрос1!$E$2:$E$5270,4) = RIGHT(A5,4)) * ([5]Запрос1!$A$2:$A$5270 >= $B$1) * ([5]Запрос1!$A$2:$A$5270 <= $B$2) * [5]Запрос1!$I$2:$I$5270 )*0.25} -> 0 | BW5: =IF(AND(C5="Ц",COUNTIF($C$3:$C$21,"Ц")=1),1000,0) + IF(AND(D5="Ц",COUNTIF($D$3:$D$21,"Ц")=1),1000,0) + IF(AND(E5="Ц",COUNTIF($E$3:$E$21,"Ц")=1),1000,0) + IF(AND(F5="Ц",COUNTIF($F$3:$F$21,"Ц")=1),1000,0) + IF(AND(G5="Ц",COUNTIF($G$3:$G$21,"Ц")=1),1000,0) + IF(AND(H5="Ц",COUNTIF($H$3:$H$21,"Ц")=1),1000,0) + IF(AND(I5="Ц",COUNTIF($I$3:$I$21,"Ц")=1),1000,0) + IF(AND(J5="Ц",COUNTIF($J$3:$J$21,"Ц")=1),1000,0) + IF(AND(K5="Ц",COUNTIF($K$3:$K$21,"Ц")=1),1000,0) + IF(AND(L5="Ц",COUNTIF($L$3:$L$21,"Ц")=1),1000,0) + IF(AND(M5="Ц",COUNTIF($M$3:$M$21,"Ц")=1),1000,0) + IF(AND(N5="Ц",COUNTIF($N$3:$N$21,"Ц")=1),1000,0) + IF(AND(O5="Ц",COUNTIF($O$3:$O$21,"Ц")=1),1000,0) + IF(AND(P5="Ц",COUNTIF($P$3:$P$21,"Ц")=1),1000,0) + IF(AND(Q5="Ц",COUNTIF($Q$3:$Q$21,"Ц")=1),1000,0) + IF(AND(R5="Ц",COUNTIF($R$3:$R$21,"Ц")=1),1000,0) + IF(AND(S5="Ц",COUNTIF($S$3:$S$21,"Ц")=1),1000,0) + IF(AND(T5="Ц",COUNTIF($T$3:$T$21,"Ц")=1),1000,0) + IF(AND(U5="Ц",COUNTIF($U$3:$U$21,"Ц")=1),1000,0) + IF(AND(V5="Ц",COUNTIF($V$3:$V$21,"Ц")=1),1000,0) + IF(AND(W5="Ц",COUNTIF($W$3:$W$21,"Ц")=1),1000,0) + IF(AND(X5="Ц",COUNTIF($X$3:$X$21,"Ц")=1),1000,0) + IF(AND(Y5="Ц",COUNTIF($Y$3:$Y$21,"Ц")=1),1000,0) + IF(AND(Z5="Ц",COUNTIF($Z$3:$Z$21,"Ц")=1),1000,0) + IF(AND(AA5="Ц",COUNTIF($AA$3:$AA$21,"Ц")=1),1000,0) + IF(AND(AB5="Ц",COUNTIF($AB$3:$AB$21,"Ц")=1),1000,0) + IF(AND(AC5="Ц",COUNTIF($AC$3:$AC$21,"Ц")=1),1000,0) + IF(AND(AD5="Ц",COUNTIF($AD$3:$AD$21,"Ц")=1),1000,0) + IF(AND(AE5="Ц",COUNTIF($AE$3:$AE$21,"Ц")=1),1000,0) + IF(AND(AF5="Ц",COUNTIF($AF$3:$AF$21,"Ц")=1),1000,0) + IF(AND(AG5="Ц",COUNTIF($AG$3:$AG$21,"Ц")=1),1000,0) -> 0 | CE5: =SUM(AU5:CD5) -> 51619.97 | CQ5: =(AU5+SUM(AY5:CD5))-SUM(CI5:CP5) -> 51619.97 | CU5: =AJ5*AQ5-AH5*AQ5 -> 0
A6: Эмиль 2404 | D6: Ох | E6: Ох | F6: Ох | J6: Ох | K6: Ох | L6: Ох | P6: Ох | Q6: Ох | R6: Ох | V6: Ох | W6: Ох | X6: Ох | AB6: Ох | AC6: Ох | AD6: Ох | AG6: Ох | AH6: 3000 | AJ6: 3500 | AL6: 0.01 | AM6: 0.05 | AN6: 1000 | AO6: =AS6-AQ6 -> 15 | AQ6: =IF(AS6>15, AS6-15, 0) -> 1 | AS6: =COUNTIF(C6:AG6, "М")+COUNTIF(C6:AG6, "Ц")+COUNTIF(C6:AG6, "П")+COUNTIF(C6:AG6, "Ох")+COUNTIF(C6:AG6, "Оз")+COUNTIF(C6:AG6, "А")+COUNTIF(C6:AG6, "Р")+(COUNTIF(C6:AG6, "05М")/2)+(COUNTIF(C6:AG6, "05Ц")/2)+(COUNTIF(C6:AG6, "05П")/2)+(COUNTIF(C6:AG6, "05Ох")/2)+(COUNTIF(C6:AG6, "05Оз")/2)+(COUNTIF(C6:AG6, "05А")/2)+(COUNTIF(C6:AG6, "05Р")/2) -> 16 | AU6: =AO6*AH6+AQ6*AJ6 -> 48500 | AY6: {=SUMPRODUCT( (RIGHT([1]Запрос1!$D$2:$D$43198,4)=RIGHT(A6,4))* ([1]Запрос1!$A$2:$A$43198>=$B$1)* ([1]Запрос1!$A$2:$A$43198<=$B$2)* [1]Запрос1!$F$2:$F$43198)*AL6} -> 1554.88 | BC6: {=SUMPRODUCT( (RIGHT([2]Запрос1!$E$2:$E$2465,4) = RIGHT(A6,4)) * ([2]Запрос1!$A$2:$A$2465 >= $B$1) * ([2]Запрос1!$A$2:$A$2465 <= $B$2) * [2]Запрос1!$I$2:$I$2465 )*AM6} -> 1453.25 | BG6: {=SUMPRODUCT( --(RIGHT([3]Запрос1!$C$2:$C$5232,4) = RIGHT(A6,4)), --([3]Запрос1!$E$2:$E$5232 >= $B$1), --([3]Запрос1!$E$2:$E$5232 <= $B$2) )*AN6} -> 1000 | BK6: {=SUMPRODUCT( (RIGHT([4]Запрос1!$E$2:$E$5389,4)=RIGHT(A6,4))* ([4]Запрос1!$A$2:$A$5389>=$B$1)* ([4]Запрос1!$A$2:$A$5389<=$B$2)* [4]Запрос1!$J$2:$J$5389 )*0.01} -> 0 | BO6: {=SUMPRODUCT( (RIGHT([5]Запрос1!$E$2:$E$5270,4) = RIGHT(A6,4)) * ([5]Запрос1!$A$2:$A$5270 >= $B$1) * ([5]Запрос1!$A$2:$A$5270 <= $B$2) * [5]Запрос1!$I$2:$I$5270 )*0.25} -> 0 | BW6: =IF(AND(C6="Ц",COUNTIF($C$3:$C$21,"Ц")=1),1000,0) + IF(AND(D6="Ц",COUNTIF($D$3:$D$21,"Ц")=1),1000,0) + IF(AND(E6="Ц",COUNTIF($E$3:$E$21,"Ц")=1),1000,0) + IF(AND(F6="Ц",COUNTIF($F$3:$F$21,"Ц")=1),1000,0) + IF(AND(G6="Ц",COUNTIF($G$3:$G$21,"Ц")=1),1000,0) + IF(AND(H6="Ц",COUNTIF($H$3:$H$21,"Ц")=1),1000,0) + IF(AND(I6="Ц",COUNTIF($I$3:$I$21,"Ц")=1),1000,0) + IF(AND(J6="Ц",COUNTIF($J$3:$J$21,"Ц")=1),1000,0) + IF(AND(K6="Ц",COUNTIF($K$3:$K$21,"Ц")=1),1000,0) + IF(AND(L6="Ц",COUNTIF($L$3:$L$21,"Ц")=1),1000,0) + IF(AND(M6="Ц",COUNTIF($M$3:$M$21,"Ц")=1),1000,0) + IF(AND(N6="Ц",COUNTIF($N$3:$N$21,"Ц")=1),1000,0) + IF(AND(O6="Ц",COUNTIF($O$3:$O$21,"Ц")=1),1000,0) + IF(AND(P6="Ц",COUNTIF($P$3:$P$21,"Ц")=1),1000,0) + IF(AND(Q6="Ц",COUNTIF($Q$3:$Q$21,"Ц")=1),1000,0) + IF(AND(R6="Ц",COUNTIF($R$3:$R$21,"Ц")=1),1000,0) + IF(AND(S6="Ц",COUNTIF($S$3:$S$21,"Ц")=1),1000,0) + IF(AND(T6="Ц",COUNTIF($T$3:$T$21,"Ц")=1),1000,0) + IF(AND(U6="Ц",COUNTIF($U$3:$U$21,"Ц")=1),1000,0) + IF(AND(V6="Ц",COUNTIF($V$3:$V$21,"Ц")=1),1000,0) + IF(AND(W6="Ц",COUNTIF($W$3:$W$21,"Ц")=1),1000,0) + IF(AND(X6="Ц",COUNTIF($X$3:$X$21,"Ц")=1),1000,0) + IF(AND(Y6="Ц",COUNTIF($Y$3:$Y$21,"Ц")=1),1000,0) + IF(AND(Z6="Ц",COUNTIF($Z$3:$Z$21,"Ц")=1),1000,0) + IF(AND(AA6="Ц",COUNTIF($AA$3:$AA$21,"Ц")=1),1000,0) + IF(AND(AB6="Ц",COUNTIF($AB$3:$AB$21,"Ц")=1),1000,0) + IF(AND(AC6="Ц",COUNTIF($AC$3:$AC$21,"Ц")=1),1000,0) + IF(AND(AD6="Ц",COUNTIF($AD$3:$AD$21,"Ц")=1),1000,0) + IF(AND(AE6="Ц",COUNTIF($AE$3:$AE$21,"Ц")=1),1000,0) + IF(AND(AF6="Ц",COUNTIF($AF$3:$AF$21,"Ц")=1),1000,0) + IF(AND(AG6="Ц",COUNTIF($AG$3:$AG$21,"Ц")=1),1000,0) -> 0 | CE6: =SUM(AU6:CD6) -> 52508.13 | CQ6: =(AU6+SUM(AY6:CD6))-SUM(CI6:CP6) -> 52508.13 | CU6: =AJ6*AQ6-AH6*AQ6 -> 500
A7: Полина 5984 | D7: М | E7: М | H7: М | I7: М | L7: М | M7: М | P7: М | Q7: М | T7: М | U7: М | Y7: М | AB7: М | AC7: М | AF7: М | AG7: М | AH7: 4000 | AJ7: 4000 | AL7: 0.01 | AM7: 0.05 | AN7: 300 | AO7: =AS7-AQ7 -> 15 | AQ7: =IF(AS7>15, AS7-15, 0) -> 0 | AS7: =COUNTIF(C7:AG7, "М")+COUNTIF(C7:AG7, "Ц")+COUNTIF(C7:AG7, "П")+COUNTIF(C7:AG7, "Ох")+COUNTIF(C7:AG7, "Оз")+COUNTIF(C7:AG7, "А")+COUNTIF(C7:AG7, "Р")+(COUNTIF(C7:AG7, "05М")/2)+(COUNTIF(C7:AG7, "05Ц")/2)+(COUNTIF(C7:AG7, "05П")/2)+(COUNTIF(C7:AG7, "05Ох")/2)+(COUNTIF(C7:AG7, "05Оз")/2)+(COUNTIF(C7:AG7, "05А")/2)+(COUNTIF(C7:AG7, "05Р")/2) -> 15 | AU7: =AO7*AH7+AQ7*AJ7 -> 60000 | AY7: {=SUMPRODUCT( (RIGHT([1]Запрос1!$D$2:$D$43198,4)=RIGHT(A7,4))* ([1]Запрос1!$A$2:$A$43198>=$B$1)* ([1]Запрос1!$A$2:$A$43198<=$B$2)* [1]Запрос1!$F$2:$F$43198)*AL7} -> 2515.54 | BC7: {=SUMPRODUCT( (RIGHT([2]Запрос1!$E$2:$E$2465,4) = RIGHT(A7,4)) * ([2]Запрос1!$A$2:$A$2465 >= $B$1) * ([2]Запрос1!$A$2:$A$2465 <= $B$2) * [2]Запрос1!$I$2:$I$2465 )*AM7} -> 2105.75 | BG7: {=SUMPRODUCT( --(RIGHT([3]Запрос1!$C$2:$C$5232,4) = RIGHT(A7,4)), --([3]Запрос1!$E$2:$E$5232 >= $B$1), --([3]Запрос1!$E$2:$E$5232 <= $B$2) )*AN7} -> 1200 | BK7: {=SUMPRODUCT( (RIGHT([4]Запрос1!$E$2:$E$5389,4)=RIGHT(A7,4))* ([4]Запрос1!$A$2:$A$5389>=$B$1)* ([4]Запрос1!$A$2:$A$5389<=$B$2)* [4]Запрос1!$J$2:$J$5389 )*0.01} -> 0 | BO7: {=SUMPRODUCT( (RIGHT([5]Запрос1!$E$2:$E$5270,4) = RIGHT(A7,4)) * ([5]Запрос1!$A$2:$A$5270 >= $B$1) * ([5]Запрос1!$A$2:$A$5270 <= $B$2) * [5]Запрос1!$I$2:$I$5270 )*0.25} -> 0 | BW7: =IF(AND(C7="Ц",COUNTIF($C$3:$C$21,"Ц")=1),1000,0) + IF(AND(D7="Ц",COUNTIF($D$3:$D$21,"Ц")=1),1000,0) + IF(AND(E7="Ц",COUNTIF($E$3:$E$21,"Ц")=1),1000,0) + IF(AND(F7="Ц",COUNTIF($F$3:$F$21,"Ц")=1),1000,0) + IF(AND(G7="Ц",COUNTIF($G$3:$G$21,"Ц")=1),1000,0) + IF(AND(H7="Ц",COUNTIF($H$3:$H$21,"Ц")=1),1000,0) + IF(AND(I7="Ц",COUNTIF($I$3:$I$21,"Ц")=1),1000,0) + IF(AND(J7="Ц",COUNTIF($J$3:$J$21,"Ц")=1),1000,0) + IF(AND(K7="Ц",COUNTIF($K$3:$K$21,"Ц")=1),1000,0) + IF(AND(L7="Ц",COUNTIF($L$3:$L$21,"Ц")=1),1000,0) + IF(AND(M7="Ц",COUNTIF($M$3:$M$21,"Ц")=1),1000,0) + IF(AND(N7="Ц",COUNTIF($N$3:$N$21,"Ц")=1),1000,0) + IF(AND(O7="Ц",COUNTIF($O$3:$O$21,"Ц")=1),1000,0) + IF(AND(P7="Ц",COUNTIF($P$3:$P$21,"Ц")=1),1000,0) + IF(AND(Q7="Ц",COUNTIF($Q$3:$Q$21,"Ц")=1),1000,0) + IF(AND(R7="Ц",COUNTIF($R$3:$R$21,"Ц")=1),1000,0) + IF(AND(S7="Ц",COUNTIF($S$3:$S$21,"Ц")=1),1000,0) + IF(AND(T7="Ц",COUNTIF($T$3:$T$21,"Ц")=1),1000,0) + IF(AND(U7="Ц",COUNTIF($U$3:$U$21,"Ц")=1),1000,0) + IF(AND(V7="Ц",COUNTIF($V$3:$V$21,"Ц")=1),1000,0) + IF(AND(W7="Ц",COUNTIF($W$3:$W$21,"Ц")=1),1000,0) + IF(AND(X7="Ц",COUNTIF($X$3:$X$21,"Ц")=1),1000,0) + IF(AND(Y7="Ц",COUNTIF($Y$3:$Y$21,"Ц")=1),1000,0) + IF(AND(Z7="Ц",COUNTIF($Z$3:$Z$21,"Ц")=1),1000,0) + IF(AND(AA7="Ц",COUNTIF($AA$3:$AA$21,"Ц")=1),1000,0) + IF(AND(AB7="Ц",COUNTIF($AB$3:$AB$21,"Ц")=1),1000,0) + IF(AND(AC7="Ц",COUNTIF($AC$3:$AC$21,"Ц")=1),1000,0) + IF(AND(AD7="Ц",COUNTIF($AD$3:$AD$21,"Ц")=1),1000,0) + IF(AND(AE7="Ц",COUNTIF($AE$3:$AE$21,"Ц")=1),1000,0) + IF(AND(AF7="Ц",COUNTIF($AF$3:$AF$21,"Ц")=1),1000,0) + IF(AND(AG7="Ц",COUNTIF($AG$3:$AG$21,"Ц")=1),1000,0) -> 0 | CE7: =SUM(AU7:CD7) -> 65821.29 | CQ7: =(AU7+SUM(AY7:CD7))-SUM(CI7:CP7) -> 65821.29 | CU7: =AJ7*AQ7-AH7*AQ7 -> 0
A8: Юля 3007 | F8: М | G8: М | H8: П | I8: П | J8: М | K8: М | M8: П | N8: П | O8: М | Q8: П | R8: М | S8: М | U8: П | V8: М | W8: М | X8: М | Z8: М | AA8: М | AC8: П | AD8: М | AE8: М | AH8: 3350 | AJ8: 3850 | AL8: 0.02 | AM8: 0.08 | AN8: 1000 | AO8: =AS8-AQ8 -> 15 | AQ8: =IF(AS8>15, AS8-15, 0) -> 6 | AS8: =COUNTIF(C8:AG8, "М")+COUNTIF(C8:AG8, "Ц")+COUNTIF(C8:AG8, "П")+COUNTIF(C8:AG8, "Ох")+COUNTIF(C8:AG8, "Оз")+COUNTIF(C8:AG8, "А")+COUNTIF(C8:AG8, "Р")+(COUNTIF(C8:AG8, "05М")/2)+(COUNTIF(C8:AG8, "05Ц")/2)+(COUNTIF(C8:AG8, "05П")/2)+(COUNTIF(C8:AG8, "05Ох")/2)+(COUNTIF(C8:AG8, "05Оз")/2)+(COUNTIF(C8:AG8, "05А")/2)+(COUNTIF(C8:AG8, "05Р")/2) -> 21 | AU8: =AO8*AH8+AQ8*AJ8 -> 73350 | AY8: {=SUMPRODUCT( (RIGHT([1]Запрос1!$D$2:$D$43198,4)=RIGHT(A8,4))* ([1]Запрос1!$A$2:$A$43198>=$B$1)* ([1]Запрос1!$A$2:$A$43198<=$B$2)* [1]Запрос1!$F$2:$F$43198)*AL8} -> 9121.9 | BC8: {=SUMPRODUCT( (RIGHT([2]Запрос1!$E$2:$E$2465,4) = RIGHT(A8,4)) * ([2]Запрос1!$A$2:$A$2465 >= $B$1) * ([2]Запрос1!$A$2:$A$2465 <= $B$2) * [2]Запрос1!$I$2:$I$2465 )*AM8} -> 6973.6 | BG8: 9000 | BK8: {=SUMPRODUCT( (RIGHT([4]Запрос1!$E$2:$E$5389,4)=RIGHT(A8,4))* ([4]Запрос1!$A$2:$A$5389>=$B$1)* ([4]Запрос1!$A$2:$A$5389<=$B$2)* [4]Запрос1!$J$2:$J$5389 )*0.01} -> 0 | BO8: {=SUMPRODUCT( (RIGHT([5]Запрос1!$E$2:$E$5270,4) = RIGHT(A8,4)) * ([5]Запрос1!$A$2:$A$5270 >= $B$1) * ([5]Запрос1!$A$2:$A$5270 <= $B$2) * [5]Запрос1!$I$2:$I$5270 )*0.25} -> 0 | BW8: =IF(AND(C8="Ц",COUNTIF($C$3:$C$21,"Ц")=1),1000,0) + IF(AND(D8="Ц",COUNTIF($D$3:$D$21,"Ц")=1),1000,0) + IF(AND(E8="Ц",COUNTIF($E$3:$E$21,"Ц")=1),1000,0) + IF(AND(F8="Ц",COUNTIF($F$3:$F$21,"Ц")=1),1000,0) + IF(AND(G8="Ц",COUNTIF($G$3:$G$21,"Ц")=1),1000,0) + IF(AND(H8="Ц",COUNTIF($H$3:$H$21,"Ц")=1),1000,0) + IF(AND(I8="Ц",COUNTIF($I$3:$I$21,"Ц")=1),1000,0) + IF(AND(J8="Ц",COUNTIF($J$3:$J$21,"Ц")=1),1000,0) + IF(AND(K8="Ц",COUNTIF($K$3:$K$21,"Ц")=1),1000,0) + IF(AND(L8="Ц",COUNTIF($L$3:$L$21,"Ц")=1),1000,0) + IF(AND(M8="Ц",COUNTIF($M$3:$M$21,"Ц")=1),1000,0) + IF(AND(N8="Ц",COUNTIF($N$3:$N$21,"Ц")=1),1000,0) + IF(AND(O8="Ц",COUNTIF($O$3:$O$21,"Ц")=1),1000,0) + IF(AND(P8="Ц",COUNTIF($P$3:$P$21,"Ц")=1),1000,0) + IF(AND(Q8="Ц",COUNTIF($Q$3:$Q$21,"Ц")=1),1000,0) + IF(AND(R8="Ц",COUNTIF($R$3:$R$21,"Ц")=1),1000,0) + IF(AND(S8="Ц",COUNTIF($S$3:$S$21,"Ц")=1),1000,0) + IF(AND(T8="Ц",COUNTIF($T$3:$T$21,"Ц")=1),1000,0) + IF(AND(U8="Ц",COUNTIF($U$3:$U$21,"Ц")=1),1000,0) + IF(AND(V8="Ц",COUNTIF($V$3:$V$21,"Ц")=1),1000,0) + IF(AND(W8="Ц",COUNTIF($W$3:$W$21,"Ц")=1),1000,0) + IF(AND(X8="Ц",COUNTIF($X$3:$X$21,"Ц")=1),1000,0) + IF(AND(Y8="Ц",COUNTIF($Y$3:$Y$21,"Ц")=1),1000,0) + IF(AND(Z8="Ц",COUNTIF($Z$3:$Z$21,"Ц")=1),1000,0) + IF(AND(AA8="Ц",COUNTIF($AA$3:$AA$21,"Ц")=1),1000,0) + IF(AND(AB8="Ц",COUNTIF($AB$3:$AB$21,"Ц")=1),1000,0) + IF(AND(AC8="Ц",COUNTIF($AC$3:$AC$21,"Ц")=1),1000,0) + IF(AND(AD8="Ц",COUNTIF($AD$3:$AD$21,"Ц")=1),1000,0) + IF(AND(AE8="Ц",COUNTIF($AE$3:$AE$21,"Ц")=1),1000,0) + IF(AND(AF8="Ц",COUNTIF($AF$3:$AF$21,"Ц")=1),1000,0) + IF(AND(AG8="Ц",COUNTIF($AG$3:$AG$21,"Ц")=1),1000,0) -> 0 | CE8: =SUM(AU8:CD8) -> 98445.5 | CI8: 150 | CM8: 75000 | CQ8: =(AU8+SUM(AY8:CD8))-SUM(CI8:CP8) -> 23295.5 | CU8: =AJ8*AQ8-AH8*AQ8 -> 3000
A9: Катя 2201 | D9: А | E9: А | H9: А | I9: А | L9: А | M9: А | N9: М | P9: А | Q9: А | T9: А | U9: А | X9: А | Y9: А | AB9: А | AC9: А | AF9: А | AG9: А | AH9: 3350 | AJ9: 3850 | AL9: 0.01 | AM9: 0.05 | AN9: 1000 | AO9: =AS9-AQ9 -> 15 | AQ9: =IF(AS9>15, AS9-15, 0) -> 2 | AS9: =COUNTIF(C9:AG9, "М")+COUNTIF(C9:AG9, "Ц")+COUNTIF(C9:AG9, "П")+COUNTIF(C9:AG9, "Ох")+COUNTIF(C9:AG9, "Оз")+COUNTIF(C9:AG9, "А")+COUNTIF(C9:AG9, "Р")+(COUNTIF(C9:AG9, "05М")/2)+(COUNTIF(C9:AG9, "05Ц")/2)+(COUNTIF(C9:AG9, "05П")/2)+(COUNTIF(C9:AG9, "05Ох")/2)+(COUNTIF(C9:AG9, "05Оз")/2)+(COUNTIF(C9:AG9, "05А")/2)+(COUNTIF(C9:AG9, "05Р")/2) -> 17 | AU9: =AO9*AH9+AQ9*AJ9 -> 57950 | AY9: {=SUMPRODUCT( (RIGHT([1]Запрос1!$D$2:$D$43198,4)=RIGHT(A9,4))* ([1]Запрос1!$A$2:$A$43198>=$B$1)* ([1]Запрос1!$A$2:$A$43198<=$B$2)* [1]Запрос1!$F$2:$F$43198)*AL9} -> 3926.99 | BC9: {=SUMPRODUCT( (RIGHT([2]Запрос1!$E$2:$E$2465,4) = RIGHT(A9,4)) * ([2]Запрос1!$A$2:$A$2465 >= $B$1) * ([2]Запрос1!$A$2:$A$2465 <= $B$2) * [2]Запрос1!$I$2:$I$2465 )*AM9} -> 2429.5 | BG9: {=SUMPRODUCT( --(RIGHT([3]Запрос1!$C$2:$C$5232,4) = RIGHT(A9,4)), --([3]Запрос1!$E$2:$E$5232 >= $B$1), --([3]Запрос1!$E$2:$E$5232 <= $B$2) )*AN9} -> 0 | BK9: {=SUMPRODUCT( (RIGHT([4]Запрос1!$E$2:$E$5389,4)=RIGHT(A9,4))* ([4]Запрос1!$A$2:$A$5389>=$B$1)* ([4]Запрос1!$A$2:$A$5389<=$B$2)* [4]Запрос1!$J$2:$J$5389 )*0.01} -> 0 | BO9: {=SUMPRODUCT( (RIGHT([5]Запрос1!$E$2:$E$5270,4) = RIGHT(A9,4)) * ([5]Запрос1!$A$2:$A$5270 >= $B$1) * ([5]Запрос1!$A$2:$A$5270 <= $B$2) * [5]Запрос1!$I$2:$I$5270 )*0.25} -> 881.75 | BW9: =IF(AND(C9="Ц",COUNTIF($C$3:$C$21,"Ц")=1),1000,0) + IF(AND(D9="Ц",COUNTIF($D$3:$D$21,"Ц")=1),1000,0) + IF(AND(E9="Ц",COUNTIF($E$3:$E$21,"Ц")=1),1000,0) + IF(AND(F9="Ц",COUNTIF($F$3:$F$21,"Ц")=1),1000,0) + IF(AND(G9="Ц",COUNTIF($G$3:$G$21,"Ц")=1),1000,0) + IF(AND(H9="Ц",COUNTIF($H$3:$H$21,"Ц")=1),1000,0) + IF(AND(I9="Ц",COUNTIF($I$3:$I$21,"Ц")=1),1000,0) + IF(AND(J9="Ц",COUNTIF($J$3:$J$21,"Ц")=1),1000,0) + IF(AND(K9="Ц",COUNTIF($K$3:$K$21,"Ц")=1),1000,0) + IF(AND(L9="Ц",COUNTIF($L$3:$L$21,"Ц")=1),1000,0) + IF(AND(M9="Ц",COUNTIF($M$3:$M$21,"Ц")=1),1000,0) + IF(AND(N9="Ц",COUNTIF($N$3:$N$21,"Ц")=1),1000,0) + IF(AND(O9="Ц",COUNTIF($O$3:$O$21,"Ц")=1),1000,0) + IF(AND(P9="Ц",COUNTIF($P$3:$P$21,"Ц")=1),1000,0) + IF(AND(Q9="Ц",COUNTIF($Q$3:$Q$21,"Ц")=1),1000,0) + IF(AND(R9="Ц",COUNTIF($R$3:$R$21,"Ц")=1),1000,0) + IF(AND(S9="Ц",COUNTIF($S$3:$S$21,"Ц")=1),1000,0) + IF(AND(T9="Ц",COUNTIF($T$3:$T$21,"Ц")=1),1000,0) + IF(AND(U9="Ц",COUNTIF($U$3:$U$21,"Ц")=1),1000,0) + IF(AND(V9="Ц",COUNTIF($V$3:$V$21,"Ц")=1),1000,0) + IF(AND(W9="Ц",COUNTIF($W$3:$W$21,"Ц")=1),1000,0) + IF(AND(X9="Ц",COUNTIF($X$3:$X$21,"Ц")=1),1000,0) + IF(AND(Y9="Ц",COUNTIF($Y$3:$Y$21,"Ц")=1),1000,0) + IF(AND(Z9="Ц",COUNTIF($Z$3:$Z$21,"Ц")=1),1000,0) + IF(AND(AA9="Ц",COUNTIF($AA$3:$AA$21,"Ц")=1),1000,0) + IF(AND(AB9="Ц",COUNTIF($AB$3:$AB$21,"Ц")=1),1000,0) + IF(AND(AC9="Ц",COUNTIF($AC$3:$AC$21,"Ц")=1),1000,0) + IF(AND(AD9="Ц",COUNTIF($AD$3:$AD$21,"Ц")=1),1000,0) + IF(AND(AE9="Ц",COUNTIF($AE$3:$AE$21,"Ц")=1),1000,0) + IF(AND(AF9="Ц",COUNTIF($AF$3:$AF$21,"Ц")=1),1000,0) + IF(AND(AG9="Ц",COUNTIF($AG$3:$AG$21,"Ц")=1),1000,0) -> 0 | CE9: =SUM(AU9:CD9) -> 65188.24 | CQ9: =(AU9+SUM(AY9:CD9))-SUM(CI9:CP9) -> 65188.24 | CU9: =AJ9*AQ9-AH9*AQ9 -> 1000
A10: Виктория 2502 | F10: А | G10: А | J10: А | K10: А | N10: А | O10: А | R10: А | S10: А | V10: А | W10: А | Z10: А | AA10: А | AD10: А | AE10: А | AH10: 3350 | AJ10: 3850 | AL10: 0.02 | AM10: 0.08 | AN10: 1000 | AO10: =AS10-AQ10 -> 14 | AQ10: =IF(AS10>15, AS10-15, 0) -> 0 | AS10: =COUNTIF(C10:AG10, "М")+COUNTIF(C10:AG10, "Ц")+COUNTIF(C10:AG10, "П")+COUNTIF(C10:AG10, "Ох")+COUNTIF(C10:AG10, "Оз")+COUNTIF(C10:AG10, "А")+COUNTIF(C10:AG10, "Р")+(COUNTIF(C10:AG10, "05М")/2)+(COUNTIF(C10:AG10, "05Ц")/2)+(COUNTIF(C10:AG10, "05П")/2)+(COUNTIF(C10:AG10, "05Ох")/2)+(COUNTIF(C10:AG10, "05Оз")/2)+(COUNTIF(C10:AG10, "05А")/2)+(COUNTIF(C10:AG10, "05Р")/2) -> 14 | AU10: =AO10*AH10+AQ10*AJ10 -> 46900 | AY10: {=SUMPRODUCT( (RIGHT([1]Запрос1!$D$2:$D$43198,4)=RIGHT(A10,4))* ([1]Запрос1!$A$2:$A$43198>=$B$1)* ([1]Запрос1!$A$2:$A$43198<=$B$2)* [1]Запрос1!$F$2:$F$43198)*AL10} -> 7432.68 | BC10: {=SUMPRODUCT( (RIGHT([2]Запрос1!$E$2:$E$2465,4) = RIGHT(A10,4)) * ([2]Запрос1!$A$2:$A$2465 >= $B$1) * ([2]Запрос1!$A$2:$A$2465 <= $B$2) * [2]Запрос1!$I$2:$I$2465 )*AM10} -> 3012 | BG10: {=SUMPRODUCT( --(RIGHT([3]Запрос1!$C$2:$C$5232,4) = RIGHT(A10,4)), --([3]Запрос1!$E$2:$E$5232 >= $B$1), --([3]Запрос1!$E$2:$E$5232 <= $B$2) )*AN10} -> 0 | BK10: {=SUMPRODUCT( (RIGHT([4]Запрос1!$E$2:$E$5389,4)=RIGHT(A10,4))* ([4]Запрос1!$A$2:$A$5389>=$B$1)* ([4]Запрос1!$A$2:$A$5389<=$B$2)* [4]Запрос1!$J$2:$J$5389 )*0.01} -> 0 | BO10: {=SUMPRODUCT( (RIGHT([5]Запрос1!$E$2:$E$5270,4) = RIGHT(A10,4)) * ([5]Запрос1!$A$2:$A$5270 >= $B$1) * ([5]Запрос1!$A$2:$A$5270 <= $B$2) * [5]Запрос1!$I$2:$I$5270 )*0.25} -> 725 | BW10: =IF(AND(C10="Ц",COUNTIF($C$3:$C$21,"Ц")=1),1000,0) + IF(AND(D10="Ц",COUNTIF($D$3:$D$21,"Ц")=1),1000,0) + IF(AND(E10="Ц",COUNTIF($E$3:$E$21,"Ц")=1),1000,0) + IF(AND(F10="Ц",COUNTIF($F$3:$F$21,"Ц")=1),1000,0) + IF(AND(G10="Ц",COUNTIF($G$3:$G$21,"Ц")=1),1000,0) + IF(AND(H10="Ц",COUNTIF($H$3:$H$21,"Ц")=1),1000,0) + IF(AND(I10="Ц",COUNTIF($I$3:$I$21,"Ц")=1),1000,0) + IF(AND(J10="Ц",COUNTIF($J$3:$J$21,"Ц")=1),1000,0) + IF(AND(K10="Ц",COUNTIF($K$3:$K$21,"Ц")=1),1000,0) + IF(AND(L10="Ц",COUNTIF($L$3:$L$21,"Ц")=1),1000,0) + IF(AND(M10="Ц",COUNTIF($M$3:$M$21,"Ц")=1),1000,0) + IF(AND(N10="Ц",COUNTIF($N$3:$N$21,"Ц")=1),1000,0) + IF(AND(O10="Ц",COUNTIF($O$3:$O$21,"Ц")=1),1000,0) + IF(AND(P10="Ц",COUNTIF($P$3:$P$21,"Ц")=1),1000,0) + IF(AND(Q10="Ц",COUNTIF($Q$3:$Q$21,"Ц")=1),1000,0) + IF(AND(R10="Ц",COUNTIF($R$3:$R$21,"Ц")=1),1000,0) + IF(AND(S10="Ц",COUNTIF($S$3:$S$21,"Ц")=1),1000,0) + IF(AND(T10="Ц",COUNTIF($T$3:$T$21,"Ц")=1),1000,0) + IF(AND(U10="Ц",COUNTIF($U$3:$U$21,"Ц")=1),1000,0) + IF(AND(V10="Ц",COUNTIF($V$3:$V$21,"Ц")=1),1000,0) + IF(AND(W10="Ц",COUNTIF($W$3:$W$21,"Ц")=1),1000,0) + IF(AND(X10="Ц",COUNTIF($X$3:$X$21,"Ц")=1),1000,0) + IF(AND(Y10="Ц",COUNTIF($Y$3:$Y$21,"Ц")=1),1000,0) + IF(AND(Z10="Ц",COUNTIF($Z$3:$Z$21,"Ц")=1),1000,0) + IF(AND(AA10="Ц",COUNTIF($AA$3:$AA$21,"Ц")=1),1000,0) + IF(AND(AB10="Ц",COUNTIF($AB$3:$AB$21,"Ц")=1),1000,0) + IF(AND(AC10="Ц",COUNTIF($AC$3:$AC$21,"Ц")=1),1000,0) + IF(AND(AD10="Ц",COUNTIF($AD$3:$AD$21,"Ц")=1),1000,0) + IF(AND(AE10="Ц",COUNTIF($AE$3:$AE$21,"Ц")=1),1000,0) + IF(AND(AF10="Ц",COUNTIF($AF$3:$AF$21,"Ц")=1),1000,0) + IF(AND(AG10="Ц",COUNTIF($AG$3:$AG$21,"Ц")=1),1000,0) -> 0 | CE10: =SUM(AU10:CD10) -> 58069.68 | CQ10: =(AU10+SUM(AY10:CD10))-SUM(CI10:CP10) -> 58069.68 | CU10: =AJ10*AQ10-AH10*AQ10 -> 0
A11: Вероника 1996 | E11: П | F11: П | K11: П | L11: П | O11: П | P11: П | S11: П | T11: П | W11: П | X11: П | Z11: П | AA11: П | AB11: П | AE11: П | AF11: П | AG11: П | AH11: 3000 | AJ11: 3500 | AL11: 0.01 | AM11: 0.05 | AN11: 300 | AO11: =AS11-AQ11 -> 15 | AQ11: =IF(AS11>15, AS11-15, 0) -> 1 | AS11: =COUNTIF(C11:AG11, "М")+COUNTIF(C11:AG11, "Ц")+COUNTIF(C11:AG11, "П")+COUNTIF(C11:AG11, "Ох")+COUNTIF(C11:AG11, "Оз")+COUNTIF(C11:AG11, "А")+COUNTIF(C11:AG11, "Р")+(COUNTIF(C11:AG11, "05М")/2)+(COUNTIF(C11:AG11, "05Ц")/2)+(COUNTIF(C11:AG11, "05П")/2)+(COUNTIF(C11:AG11, "05Ох")/2)+(COUNTIF(C11:AG11, "05Оз")/2)+(COUNTIF(C11:AG11, "05А")/2)+(COUNTIF(C11:AG11, "05Р")/2) -> 16 | AU11: =AO11*AH11+AQ11*AJ11 -> 48500 | AY11: {=SUMPRODUCT( (RIGHT([1]Запрос1!$D$2:$D$43198,4)=RIGHT(A11,4))* ([1]Запрос1!$A$2:$A$43198>=$B$1)* ([1]Запрос1!$A$2:$A$43198<=$B$2)* [1]Запрос1!$F$2:$F$43198)*AL11} -> 6687.75 | BC11: {=SUMPRODUCT( (RIGHT([2]Запрос1!$E$2:$E$2465,4) = RIGHT(A11,4)) * ([2]Запрос1!$A$2:$A$2465 >= $B$1) * ([2]Запрос1!$A$2:$A$2465 <= $B$2) * [2]Запрос1!$I$2:$I$2465 )*AM11} -> 4377.5 | BG11: {=SUMPRODUCT( --(RIGHT([3]Запрос1!$C$2:$C$5232,4) = RIGHT(A11,4)), --([3]Запрос1!$E$2:$E$5232 >= $B$1), --([3]Запрос1!$E$2:$E$5232 <= $B$2) )*AN11} -> 1200 | BK11: {=SUMPRODUCT( (RIGHT([4]Запрос1!$E$2:$E$5389,4)=RIGHT(A11,4))* ([4]Запрос1!$A$2:$A$5389>=$B$1)* ([4]Запрос1!$A$2:$A$5389<=$B$2)* [4]Запрос1!$J$2:$J$5389 )*0.01} -> 0 | BO11: {=SUMPRODUCT( (RIGHT([5]Запрос1!$E$2:$E$5270,4) = RIGHT(A11,4)) * ([5]Запрос1!$A$2:$A$5270 >= $B$1) * ([5]Запрос1!$A$2:$A$5270 <= $B$2) * [5]Запрос1!$I$2:$I$5270 )*0.25} -> 0 | BW11: =IF(AND(C11="Ц",COUNTIF($C$3:$C$21,"Ц")=1),1000,0) + IF(AND(D11="Ц",COUNTIF($D$3:$D$21,"Ц")=1),1000,0) + IF(AND(E11="Ц",COUNTIF($E$3:$E$21,"Ц")=1),1000,0) + IF(AND(F11="Ц",COUNTIF($F$3:$F$21,"Ц")=1),1000,0) + IF(AND(G11="Ц",COUNTIF($G$3:$G$21,"Ц")=1),1000,0) + IF(AND(H11="Ц",COUNTIF($H$3:$H$21,"Ц")=1),1000,0) + IF(AND(I11="Ц",COUNTIF($I$3:$I$21,"Ц")=1),1000,0) + IF(AND(J11="Ц",COUNTIF($J$3:$J$21,"Ц")=1),1000,0) + IF(AND(K11="Ц",COUNTIF($K$3:$K$21,"Ц")=1),1000,0) + IF(AND(L11="Ц",COUNTIF($L$3:$L$21,"Ц")=1),1000,0) + IF(AND(M11="Ц",COUNTIF($M$3:$M$21,"Ц")=1),1000,0) + IF(AND(N11="Ц",COUNTIF($N$3:$N$21,"Ц")=1),1000,0) + IF(AND(O11="Ц",COUNTIF($O$3:$O$21,"Ц")=1),1000,0) + IF(AND(P11="Ц",COUNTIF($P$3:$P$21,"Ц")=1),1000,0) + IF(AND(Q11="Ц",COUNTIF($Q$3:$Q$21,"Ц")=1),1000,0) + IF(AND(R11="Ц",COUNTIF($R$3:$R$21,"Ц")=1),1000,0) + IF(AND(S11="Ц",COUNTIF($S$3:$S$21,"Ц")=1),1000,0) + IF(AND(T11="Ц",COUNTIF($T$3:$T$21,"Ц")=1),1000,0) + IF(AND(U11="Ц",COUNTIF($U$3:$U$21,"Ц")=1),1000,0) + IF(AND(V11="Ц",COUNTIF($V$3:$V$21,"Ц")=1),1000,0) + IF(AND(W11="Ц",COUNTIF($W$3:$W$21,"Ц")=1),1000,0) + IF(AND(X11="Ц",COUNTIF($X$3:$X$21,"Ц")=1),1000,0) + IF(AND(Y11="Ц",COUNTIF($Y$3:$Y$21,"Ц")=1),1000,0) + IF(AND(Z11="Ц",COUNTIF($Z$3:$Z$21,"Ц")=1),1000,0) + IF(AND(AA11="Ц",COUNTIF($AA$3:$AA$21,"Ц")=1),1000,0) + IF(AND(AB11="Ц",COUNTIF($AB$3:$AB$21,"Ц")=1),1000,0) + IF(AND(AC11="Ц",COUNTIF($AC$3:$AC$21,"Ц")=1),1000,0) + IF(AND(AD11="Ц",COUNTIF($AD$3:$AD$21,"Ц")=1),1000,0) + IF(AND(AE11="Ц",COUNTIF($AE$3:$AE$21,"Ц")=1),1000,0) + IF(AND(AF11="Ц",COUNTIF($AF$3:$AF$21,"Ц")=1),1000,0) + IF(AND(AG11="Ц",COUNTIF($AG$3:$AG$21,"Ц")=1),1000,0) -> 0 | CE11: =SUM(AU11:CD11) -> 60765.25 | CQ11: =(AU11+SUM(AY11:CD11))-SUM(CI11:CP11) -> 60765.25 | CU11: =AJ11*AQ11-AH11*AQ11 -> 500
A12: Валерия 2106 | F12: Оз | G12: Оз | J12: Оз | K12: Оз | N12: Оз | O12: Оз | R12: Оз | S12: Оз | V12: Оз | W12: Оз | Z12: Оз | AA12: Оз | AD12: Оз | AE12: Оз | AH12: 3350 | AJ12: 3850 | AL12: 0.02 | AM12: 0.08 | AN12: 1000 | AO12: =AS12-AQ12 -> 14 | AQ12: =IF(AS12>15, AS12-15, 0) -> 0 | AS12: =COUNTIF(C12:AG12, "М")+COUNTIF(C12:AG12, "Ц")+COUNTIF(C12:AG12, "П")+COUNTIF(C12:AG12, "Ох")+COUNTIF(C12:AG12, "Оз")+COUNTIF(C12:AG12, "А")+COUNTIF(C12:AG12, "Р")+(COUNTIF(C12:AG12, "05М")/2)+(COUNTIF(C12:AG12, "05Ц")/2)+(COUNTIF(C12:AG12, "05П")/2)+(COUNTIF(C12:AG12, "05Ох")/2)+(COUNTIF(C12:AG12, "05Оз")/2)+(COUNTIF(C12:AG12, "05А")/2)+(COUNTIF(C12:AG12, "05Р")/2) -> 14 | AU12: =AO12*AH12+AQ12*AJ12 -> 46900 | AY12: {=SUMPRODUCT( (RIGHT([1]Запрос1!$D$2:$D$43198,4)=RIGHT(A12,4))* ([1]Запрос1!$A$2:$A$43198>=$B$1)* ([1]Запрос1!$A$2:$A$43198<=$B$2)* [1]Запрос1!$F$2:$F$43198)*AL12} -> 3648.7 | BC12: {=SUMPRODUCT( (RIGHT([2]Запрос1!$E$2:$E$2465,4) = RIGHT(A12,4)) * ([2]Запрос1!$A$2:$A$2465 >= $B$1) * ([2]Запрос1!$A$2:$A$2465 <= $B$2) * [2]Запрос1!$I$2:$I$2465 )*AM12} -> 1471.2 | BG12: {=SUMPRODUCT( --(RIGHT([3]Запрос1!$C$2:$C$5232,4) = RIGHT(A12,4)), --([3]Запрос1!$E$2:$E$5232 >= $B$1), --([3]Запрос1!$E$2:$E$5232 <= $B$2) )*AN12} -> 0 | BK12: {=SUMPRODUCT( (RIGHT([4]Запрос1!$E$2:$E$5389,4)=RIGHT(A12,4))* ([4]Запрос1!$A$2:$A$5389>=$B$1)* ([4]Запрос1!$A$2:$A$5389<=$B$2)* [4]Запрос1!$J$2:$J$5389 )*0.01} -> 0 | BO12: {=SUMPRODUCT( (RIGHT([5]Запрос1!$E$2:$E$5270,4) = RIGHT(A12,4)) * ([5]Запрос1!$A$2:$A$5270 >= $B$1) * ([5]Запрос1!$A$2:$A$5270 <= $B$2) * [5]Запрос1!$I$2:$I$5270 )*0.25} -> 0 | BW12: =IF(AND(C12="Ц",COUNTIF($C$3:$C$21,"Ц")=1),1000,0) + IF(AND(D12="Ц",COUNTIF($D$3:$D$21,"Ц")=1),1000,0) + IF(AND(E12="Ц",COUNTIF($E$3:$E$21,"Ц")=1),1000,0) + IF(AND(F12="Ц",COUNTIF($F$3:$F$21,"Ц")=1),1000,0) + IF(AND(G12="Ц",COUNTIF($G$3:$G$21,"Ц")=1),1000,0) + IF(AND(H12="Ц",COUNTIF($H$3:$H$21,"Ц")=1),1000,0) + IF(AND(I12="Ц",COUNTIF($I$3:$I$21,"Ц")=1),1000,0) + IF(AND(J12="Ц",COUNTIF($J$3:$J$21,"Ц")=1),1000,0) + IF(AND(K12="Ц",COUNTIF($K$3:$K$21,"Ц")=1),1000,0) + IF(AND(L12="Ц",COUNTIF($L$3:$L$21,"Ц")=1),1000,0) + IF(AND(M12="Ц",COUNTIF($M$3:$M$21,"Ц")=1),1000,0) + IF(AND(N12="Ц",COUNTIF($N$3:$N$21,"Ц")=1),1000,0) + IF(AND(O12="Ц",COUNTIF($O$3:$O$21,"Ц")=1),1000,0) + IF(AND(P12="Ц",COUNTIF($P$3:$P$21,"Ц")=1),1000,0) + IF(AND(Q12="Ц",COUNTIF($Q$3:$Q$21,"Ц")=1),1000,0) + IF(AND(R12="Ц",COUNTIF($R$3:$R$21,"Ц")=1),1000,0) + IF(AND(S12="Ц",COUNTIF($S$3:$S$21,"Ц")=1),1000,0) + IF(AND(T12="Ц",COUNTIF($T$3:$T$21,"Ц")=1),1000,0) + IF(AND(U12="Ц",COUNTIF($U$3:$U$21,"Ц")=1),1000,0) + IF(AND(V12="Ц",COUNTIF($V$3:$V$21,"Ц")=1),1000,0) + IF(AND(W12="Ц",COUNTIF($W$3:$W$21,"Ц")=1),1000,0) + IF(AND(X12="Ц",COUNTIF($X$3:$X$21,"Ц")=1),1000,0) + IF(AND(Y12="Ц",COUNTIF($Y$3:$Y$21,"Ц")=1),1000,0) + IF(AND(Z12="Ц",COUNTIF($Z$3:$Z$21,"Ц")=1),1000,0) + IF(AND(AA12="Ц",COUNTIF($AA$3:$AA$21,"Ц")=1),1000,0) + IF(AND(AB12="Ц",COUNTIF($AB$3:$AB$21,"Ц")=1),1000,0) + IF(AND(AC12="Ц",COUNTIF($AC$3:$AC$21,"Ц")=1),1000,0) + IF(AND(AD12="Ц",COUNTIF($AD$3:$AD$21,"Ц")=1),1000,0) + IF(AND(AE12="Ц",COUNTIF($AE$3:$AE$21,"Ц")=1),1000,0) + IF(AND(AF12="Ц",COUNTIF($AF$3:$AF$21,"Ц")=1),1000,0) + IF(AND(AG12="Ц",COUNTIF($AG$3:$AG$21,"Ц")=1),1000,0) -> 0 | CE12: =SUM(AU12:CD12) -> 52019.9 | CQ12: =(AU12+SUM(AY12:CD12))-SUM(CI12:CP12) -> 52019.9 | CU12: =AJ12*AQ12-AH12*AQ12 -> 0
A13: Любовь 1302 | D13: Оз | E13: Оз | H13: Оз | I13: Оз | L13: Оз | M13: Оз | P13: Оз | Q13: Оз | T13: Оз | U13: Оз | X13: Оз | Y13: Оз | AB13: Оз | AC13: Оз | AF13: Оз | AG13: Оз | AH13: 3350 | AJ13: 3850 | AL13: 0.02 | AM13: 0.08 | AN13: 1000 | AO13: =AS13-AQ13 -> 15 | AQ13: =IF(AS13>15, AS13-15, 0) -> 1 | AS13: =COUNTIF(C13:AG13, "М")+COUNTIF(C13:AG13, "Ц")+COUNTIF(C13:AG13, "П")+COUNTIF(C13:AG13, "Ох")+COUNTIF(C13:AG13, "Оз")+COUNTIF(C13:AG13, "А")+COUNTIF(C13:AG13, "Р")+(COUNTIF(C13:AG13, "05М")/2)+(COUNTIF(C13:AG13, "05Ц")/2)+(COUNTIF(C13:AG13, "05П")/2)+(COUNTIF(C13:AG13, "05Ох")/2)+(COUNTIF(C13:AG13, "05Оз")/2)+(COUNTIF(C13:AG13, "05А")/2)+(COUNTIF(C13:AG13, "05Р")/2) -> 16 | AU13: =AO13*AH13+AQ13*AJ13 -> 54100 | AY13: {=SUMPRODUCT( (RIGHT([1]Запрос1!$D$2:$D$43198,4)=RIGHT(A13,4))* ([1]Запрос1!$A$2:$A$43198>=$B$1)* ([1]Запрос1!$A$2:$A$43198<=$B$2)* [1]Запрос1!$F$2:$F$43198)*AL13} -> 2784.22 | BC13: {=SUMPRODUCT( (RIGHT([2]Запрос1!$E$2:$E$2465,4) = RIGHT(A13,4)) * ([2]Запрос1!$A$2:$A$2465 >= $B$1) * ([2]Запрос1!$A$2:$A$2465 <= $B$2) * [2]Запрос1!$I$2:$I$2465 )*AM13} -> 1111.2 | BG13: {=SUMPRODUCT( --(RIGHT([3]Запрос1!$C$2:$C$5232,4) = RIGHT(A13,4)), --([3]Запрос1!$E$2:$E$5232 >= $B$1), --([3]Запрос1!$E$2:$E$5232 <= $B$2) )*AN13} -> 0 | BK13: {=SUMPRODUCT( (RIGHT([4]Запрос1!$E$2:$E$5389,4)=RIGHT(A13,4))* ([4]Запрос1!$A$2:$A$5389>=$B$1)* ([4]Запрос1!$A$2:$A$5389<=$B$2)* [4]Запрос1!$J$2:$J$5389 )*0.01} -> 0 | BO13: {=SUMPRODUCT( (RIGHT([5]Запрос1!$E$2:$E$5270,4) = RIGHT(A13,4)) * ([5]Запрос1!$A$2:$A$5270 >= $B$1) * ([5]Запрос1!$A$2:$A$5270 <= $B$2) * [5]Запрос1!$I$2:$I$5270 )*0.25} -> 0 | BW13: =IF(AND(C13="Ц",COUNTIF($C$3:$C$21,"Ц")=1),1000,0) + IF(AND(D13="Ц",COUNTIF($D$3:$D$21,"Ц")=1),1000,0) + IF(AND(E13="Ц",COUNTIF($E$3:$E$21,"Ц")=1),1000,0) + IF(AND(F13="Ц",COUNTIF($F$3:$F$21,"Ц")=1),1000,0) + IF(AND(G13="Ц",COUNTIF($G$3:$G$21,"Ц")=1),1000,0) + IF(AND(H13="Ц",COUNTIF($H$3:$H$21,"Ц")=1),1000,0) + IF(AND(I13="Ц",COUNTIF($I$3:$I$21,"Ц")=1),1000,0) + IF(AND(J13="Ц",COUNTIF($J$3:$J$21,"Ц")=1),1000,0) + IF(AND(K13="Ц",COUNTIF($K$3:$K$21,"Ц")=1),1000,0) + IF(AND(L13="Ц",COUNTIF($L$3:$L$21,"Ц")=1),1000,0) + IF(AND(M13="Ц",COUNTIF($M$3:$M$21,"Ц")=1),1000,0) + IF(AND(N13="Ц",COUNTIF($N$3:$N$21,"Ц")=1),1000,0) + IF(AND(O13="Ц",COUNTIF($O$3:$O$21,"Ц")=1),1000,0) + IF(AND(P13="Ц",COUNTIF($P$3:$P$21,"Ц")=1),1000,0) + IF(AND(Q13="Ц",COUNTIF($Q$3:$Q$21,"Ц")=1),1000,0) + IF(AND(R13="Ц",COUNTIF($R$3:$R$21,"Ц")=1),1000,0) + IF(AND(S13="Ц",COUNTIF($S$3:$S$21,"Ц")=1),1000,0) + IF(AND(T13="Ц",COUNTIF($T$3:$T$21,"Ц")=1),1000,0) + IF(AND(U13="Ц",COUNTIF($U$3:$U$21,"Ц")=1),1000,0) + IF(AND(V13="Ц",COUNTIF($V$3:$V$21,"Ц")=1),1000,0) + IF(AND(W13="Ц",COUNTIF($W$3:$W$21,"Ц")=1),1000,0) + IF(AND(X13="Ц",COUNTIF($X$3:$X$21,"Ц")=1),1000,0) + IF(AND(Y13="Ц",COUNTIF($Y$3:$Y$21,"Ц")=1),1000,0) + IF(AND(Z13="Ц",COUNTIF($Z$3:$Z$21,"Ц")=1),1000,0) + IF(AND(AA13="Ц",COUNTIF($AA$3:$AA$21,"Ц")=1),1000,0) + IF(AND(AB13="Ц",COUNTIF($AB$3:$AB$21,"Ц")=1),1000,0) + IF(AND(AC13="Ц",COUNTIF($AC$3:$AC$21,"Ц")=1),1000,0) + IF(AND(AD13="Ц",COUNTIF($AD$3:$AD$21,"Ц")=1),1000,0) + IF(AND(AE13="Ц",COUNTIF($AE$3:$AE$21,"Ц")=1),1000,0) + IF(AND(AF13="Ц",COUNTIF($AF$3:$AF$21,"Ц")=1),1000,0) + IF(AND(AG13="Ц",COUNTIF($AG$3:$AG$21,"Ц")=1),1000,0) -> 0 | CE13: =SUM(AU13:CD13) -> 57995.42 | CQ13: =(AU13+SUM(AY13:CD13))-SUM(CI13:CP13) -> 57995.42 | CU13: =AJ13*AQ13-AH13*AQ13 -> 500
A14: Алекс 2104 | D14: П | G14: П | J14: П | Y14: П | AH14: 4500 | AJ14: 4500 | AL14: 0 | AM14: 0 | AN14: 0 | AO14: =AS14-AQ14 -> 4 | AQ14: =IF(AS14>15, AS14-15, 0) -> 0 | AS14: =COUNTIF(C14:AG14, "М")+COUNTIF(C14:AG14, "Ц")+COUNTIF(C14:AG14, "П")+COUNTIF(C14:AG14, "Ох")+COUNTIF(C14:AG14, "Оз")+COUNTIF(C14:AG14, "А")+COUNTIF(C14:AG14, "Р")+(COUNTIF(C14:AG14, "05М")/2)+(COUNTIF(C14:AG14, "05Ц")/2)+(COUNTIF(C14:AG14, "05П")/2)+(COUNTIF(C14:AG14, "05Ох")/2)+(COUNTIF(C14:AG14, "05Оз")/2)+(COUNTIF(C14:AG14, "05А")/2)+(COUNTIF(C14:AG14, "05Р")/2) -> 4 | AU14: =AO14*AH14+AQ14*AJ14 -> 18000 | AY14: {=SUMPRODUCT( (RIGHT([1]Запрос1!$D$2:$D$43198,4)=RIGHT(A14,4))* ([1]Запрос1!$A$2:$A$43198>=$B$1)* ([1]Запрос1!$A$2:$A$43198<=$B$2)* [1]Запрос1!$F$2:$F$43198)*AL14} -> 0 | BC14: {=SUMPRODUCT( (RIGHT([2]Запрос1!$E$2:$E$2465,4) = RIGHT(A14,4)) * ([2]Запрос1!$A$2:$A$2465 >= $B$1) * ([2]Запрос1!$A$2:$A$2465 <= $B$2) * [2]Запрос1!$I$2:$I$2465 )*AM14} -> 0 | BG14: {=SUMPRODUCT( --(RIGHT([3]Запрос1!$C$2:$C$5232,4) = RIGHT(A14,4)), --([3]Запрос1!$E$2:$E$5232 >= $B$1), --([3]Запрос1!$E$2:$E$5232 <= $B$2) )*AN14} -> 0 | BK14: {=SUMPRODUCT( (RIGHT([4]Запрос1!$E$2:$E$5389,4)=RIGHT(A14,4))* ([4]Запрос1!$A$2:$A$5389>=$B$1)* ([4]Запрос1!$A$2:$A$5389<=$B$2)* [4]Запрос1!$J$2:$J$5389 )*0.01} -> 0 | BO14: 0 | BW14: =IF(AND(C14="Ц",COUNTIF($C$3:$C$21,"Ц")=1),1000,0) + IF(AND(D14="Ц",COUNTIF($D$3:$D$21,"Ц")=1),1000,0) + IF(AND(E14="Ц",COUNTIF($E$3:$E$21,"Ц")=1),1000,0) + IF(AND(F14="Ц",COUNTIF($F$3:$F$21,"Ц")=1),1000,0) + IF(AND(G14="Ц",COUNTIF($G$3:$G$21,"Ц")=1),1000,0) + IF(AND(H14="Ц",COUNTIF($H$3:$H$21,"Ц")=1),1000,0) + IF(AND(I14="Ц",COUNTIF($I$3:$I$21,"Ц")=1),1000,0) + IF(AND(J14="Ц",COUNTIF($J$3:$J$21,"Ц")=1),1000,0) + IF(AND(K14="Ц",COUNTIF($K$3:$K$21,"Ц")=1),1000,0) + IF(AND(L14="Ц",COUNTIF($L$3:$L$21,"Ц")=1),1000,0) + IF(AND(M14="Ц",COUNTIF($M$3:$M$21,"Ц")=1),1000,0) + IF(AND(N14="Ц",COUNTIF($N$3:$N$21,"Ц")=1),1000,0) + IF(AND(O14="Ц",COUNTIF($O$3:$O$21,"Ц")=1),1000,0) + IF(AND(P14="Ц",COUNTIF($P$3:$P$21,"Ц")=1),1000,0) + IF(AND(Q14="Ц",COUNTIF($Q$3:$Q$21,"Ц")=1),1000,0) + IF(AND(R14="Ц",COUNTIF($R$3:$R$21,"Ц")=1),1000,0) + IF(AND(S14="Ц",COUNTIF($S$3:$S$21,"Ц")=1),1000,0) + IF(AND(T14="Ц",COUNTIF($T$3:$T$21,"Ц")=1),1000,0) + IF(AND(U14="Ц",COUNTIF($U$3:$U$21,"Ц")=1),1000,0) + IF(AND(V14="Ц",COUNTIF($V$3:$V$21,"Ц")=1),1000,0) + IF(AND(W14="Ц",COUNTIF($W$3:$W$21,"Ц")=1),1000,0) + IF(AND(X14="Ц",COUNTIF($X$3:$X$21,"Ц")=1),1000,0) + IF(AND(Y14="Ц",COUNTIF($Y$3:$Y$21,"Ц")=1),1000,0) + IF(AND(Z14="Ц",COUNTIF($Z$3:$Z$21,"Ц")=1),1000,0) + IF(AND(AA14="Ц",COUNTIF($AA$3:$AA$21,"Ц")=1),1000,0) + IF(AND(AB14="Ц",COUNTIF($AB$3:$AB$21,"Ц")=1),1000,0) + IF(AND(AC14="Ц",COUNTIF($AC$3:$AC$21,"Ц")=1),1000,0) + IF(AND(AD14="Ц",COUNTIF($AD$3:$AD$21,"Ц")=1),1000,0) + IF(AND(AE14="Ц",COUNTIF($AE$3:$AE$21,"Ц")=1),1000,0) + IF(AND(AF14="Ц",COUNTIF($AF$3:$AF$21,"Ц")=1),1000,0) + IF(AND(AG14="Ц",COUNTIF($AG$3:$AG$21,"Ц")=1),1000,0) -> 0 | CE14: =SUM(AU14:CD14) -> 18000 | CQ14: =(AU14+SUM(AY14:CD14))-SUM(CI14:CP14) -> 18000 | CU14: =AJ14*AQ14-AH14*AQ14 -> 0
A15: Марина 0208 | V15: П | AD15: П | AH15: 4500 | AJ15: 4500 | AL15: 0 | AM15: 0 | AN15: 0 | AO15: =AS15-AQ15 -> 2 | AQ15: =IF(AS15>15, AS15-15, 0) -> 0 | AS15: =COUNTIF(C15:AG15, "М")+COUNTIF(C15:AG15, "Ц")+COUNTIF(C15:AG15, "П")+COUNTIF(C15:AG15, "Ох")+COUNTIF(C15:AG15, "Оз")+COUNTIF(C15:AG15, "А")+COUNTIF(C15:AG15, "Р")+(COUNTIF(C15:AG15, "05М")/2)+(COUNTIF(C15:AG15, "05Ц")/2)+(COUNTIF(C15:AG15, "05П")/2)+(COUNTIF(C15:AG15, "05Ох")/2)+(COUNTIF(C15:AG15, "05Оз")/2)+(COUNTIF(C15:AG15, "05А")/2)+(COUNTIF(C15:AG15, "05Р")/2) -> 2 | AU15: =AO15*AH15+AQ15*AJ15 -> 9000 | AY15: {=SUMPRODUCT( (RIGHT([1]Запрос1!$D$2:$D$43198,4)=RIGHT(A15,4))* ([1]Запрос1!$A$2:$A$43198>=$B$1)* ([1]Запрос1!$A$2:$A$43198<=$B$2)* [1]Запрос1!$F$2:$F$43198)*AL15} -> 0 | BC15: {=SUMPRODUCT( (RIGHT([2]Запрос1!$E$2:$E$2465,4) = RIGHT(A15,4)) * ([2]Запрос1!$A$2:$A$2465 >= $B$1) * ([2]Запрос1!$A$2:$A$2465 <= $B$2) * [2]Запрос1!$I$2:$I$2465 )*AM15} -> 0 | BG15: {=SUMPRODUCT( --(RIGHT([3]Запрос1!$C$2:$C$5232,4) = RIGHT(A15,4)), --([3]Запрос1!$E$2:$E$5232 >= $B$1), --([3]Запрос1!$E$2:$E$5232 <= $B$2) )*AN15} -> 0 | BK15: {=SUMPRODUCT( (RIGHT([4]Запрос1!$E$2:$E$5389,4)=RIGHT(A15,4))* ([4]Запрос1!$A$2:$A$5389>=$B$1)* ([4]Запрос1!$A$2:$A$5389<=$B$2)* [4]Запрос1!$J$2:$J$5389 )*0.01} -> 0 | BO15: {=SUMPRODUCT( (RIGHT([5]Запрос1!$E$2:$E$5270,4) = RIGHT(A15,4)) * ([5]Запрос1!$A$2:$A$5270 >= $B$1) * ([5]Запрос1!$A$2:$A$5270 <= $B$2) * [5]Запрос1!$I$2:$I$5270 )*0.25} -> 0 | BW15: =IF(AND(C15="Ц",COUNTIF($C$3:$C$21,"Ц")=1),1000,0) + IF(AND(D15="Ц",COUNTIF($D$3:$D$21,"Ц")=1),1000,0) + IF(AND(E15="Ц",COUNTIF($E$3:$E$21,"Ц")=1),1000,0) + IF(AND(F15="Ц",COUNTIF($F$3:$F$21,"Ц")=1),1000,0) + IF(AND(G15="Ц",COUNTIF($G$3:$G$21,"Ц")=1),1000,0) + IF(AND(H15="Ц",COUNTIF($H$3:$H$21,"Ц")=1),1000,0) + IF(AND(I15="Ц",COUNTIF($I$3:$I$21,"Ц")=1),1000,0) + IF(AND(J15="Ц",COUNTIF($J$3:$J$21,"Ц")=1),1000,0) + IF(AND(K15="Ц",COUNTIF($K$3:$K$21,"Ц")=1),1000,0) + IF(AND(L15="Ц",COUNTIF($L$3:$L$21,"Ц")=1),1000,0) + IF(AND(M15="Ц",COUNTIF($M$3:$M$21,"Ц")=1),1000,0) + IF(AND(N15="Ц",COUNTIF($N$3:$N$21,"Ц")=1),1000,0) + IF(AND(O15="Ц",COUNTIF($O$3:$O$21,"Ц")=1),1000,0) + IF(AND(P15="Ц",COUNTIF($P$3:$P$21,"Ц")=1),1000,0) + IF(AND(Q15="Ц",COUNTIF($Q$3:$Q$21,"Ц")=1),1000,0) + IF(AND(R15="Ц",COUNTIF($R$3:$R$21,"Ц")=1),1000,0) + IF(AND(S15="Ц",COUNTIF($S$3:$S$21,"Ц")=1),1000,0) + IF(AND(T15="Ц",COUNTIF($T$3:$T$21,"Ц")=1),1000,0) + IF(AND(U15="Ц",COUNTIF($U$3:$U$21,"Ц")=1),1000,0) + IF(AND(V15="Ц",COUNTIF($V$3:$V$21,"Ц")=1),1000,0) + IF(AND(W15="Ц",COUNTIF($W$3:$W$21,"Ц")=1),1000,0) + IF(AND(X15="Ц",COUNTIF($X$3:$X$21,"Ц")=1),1000,0) + IF(AND(Y15="Ц",COUNTIF($Y$3:$Y$21,"Ц")=1),1000,0) + IF(AND(Z15="Ц",COUNTIF($Z$3:$Z$21,"Ц")=1),1000,0) + IF(AND(AA15="Ц",COUNTIF($AA$3:$AA$21,"Ц")=1),1000,0) + IF(AND(AB15="Ц",COUNTIF($AB$3:$AB$21,"Ц")=1),1000,0) + IF(AND(AC15="Ц",COUNTIF($AC$3:$AC$21,"Ц")=1),1000,0) + IF(AND(AD15="Ц",COUNTIF($AD$3:$AD$21,"Ц")=1),1000,0) + IF(AND(AE15="Ц",COUNTIF($AE$3:$AE$21,"Ц")=1),1000,0) + IF(AND(AF15="Ц",COUNTIF($AF$3:$AF$21,"Ц")=1),1000,0) + IF(AND(AG15="Ц",COUNTIF($AG$3:$AG$21,"Ц")=1),1000,0) -> 0 | CE15: =SUM(AU15:CD15) -> 9000 | CQ15: =(AU15+SUM(AY15:CD15))-SUM(CI15:CP15) -> 9000 | CU15: =AJ15*AQ15-AH15*AQ15 -> 0
AO16: =AS16-AQ16 -> 0 | AQ16: =IF(AS16>15, AS16-15, 0) -> 0 | AS16: =COUNTIF(C16:AG16, "М")+COUNTIF(C16:AG16, "Ц")+COUNTIF(C16:AG16, "П")+COUNTIF(C16:AG16, "Ох")+COUNTIF(C16:AG16, "Оз")+COUNTIF(C16:AG16, "А")+COUNTIF(C16:AG16, "Р")+(COUNTIF(C16:AG16, "05М")/2)+(COUNTIF(C16:AG16, "05Ц")/2)+(COUNTIF(C16:AG16, "05П")/2)+(COUNTIF(C16:AG16, "05Ох")/2)+(COUNTIF(C16:AG16, "05Оз")/2)+(COUNTIF(C16:AG16, "05А")/2)+(COUNTIF(C16:AG16, "05Р")/2) -> 0 | AU16: =AO16*AH16+AQ16*AJ16 -> 0 | AY16: {=SUMPRODUCT( (RIGHT([1]Запрос1!$D$2:$D$43198,4)=RIGHT(A16,4))* ([1]Запрос1!$A$2:$A$43198>=$B$1)* ([1]Запрос1!$A$2:$A$43198<=$B$2)* [1]Запрос1!$F$2:$F$43198)*AL16} -> 0 | BC16: {=SUMPRODUCT( (RIGHT([2]Запрос1!$E$2:$E$2465,4) = RIGHT(A16,4)) * ([2]Запрос1!$A$2:$A$2465 >= $B$1) * ([2]Запрос1!$A$2:$A$2465 <= $B$2) * [2]Запрос1!$I$2:$I$2465 )*AM16} -> 0 | BG16: {=SUMPRODUCT( --(RIGHT([3]Запрос1!$C$2:$C$5232,4) = RIGHT(A16,4)), --([3]Запрос1!$E$2:$E$5232 >= $B$1), --([3]Запрос1!$E$2:$E$5232 <= $B$2) )*AN16} -> 0 | BK16: {=SUMPRODUCT( (RIGHT([4]Запрос1!$E$2:$E$5389,4)=RIGHT(A16,4))* ([4]Запрос1!$A$2:$A$5389>=$B$1)* ([4]Запрос1!$A$2:$A$5389<=$B$2)* [4]Запрос1!$J$2:$J$5389 )*0.01} -> 0 | BO16: {=SUMPRODUCT( (RIGHT([5]Запрос1!$E$2:$E$5270,4) = RIGHT(A16,4)) * ([5]Запрос1!$A$2:$A$5270 >= $B$1) * ([5]Запрос1!$A$2:$A$5270 <= $B$2) * [5]Запрос1!$I$2:$I$5270 )*0.25} -> 0 | BW16: =IF(AND(C16="Ц",COUNTIF($C$3:$C$21,"Ц")=1),1000,0) + IF(AND(D16="Ц",COUNTIF($D$3:$D$21,"Ц")=1),1000,0) + IF(AND(E16="Ц",COUNTIF($E$3:$E$21,"Ц")=1),1000,0) + IF(AND(F16="Ц",COUNTIF($F$3:$F$21,"Ц")=1),1000,0) + IF(AND(G16="Ц",COUNTIF($G$3:$G$21,"Ц")=1),1000,0) + IF(AND(H16="Ц",COUNTIF($H$3:$H$21,"Ц")=1),1000,0) + IF(AND(I16="Ц",COUNTIF($I$3:$I$21,"Ц")=1),1000,0) + IF(AND(J16="Ц",COUNTIF($J$3:$J$21,"Ц")=1),1000,0) + IF(AND(K16="Ц",COUNTIF($K$3:$K$21,"Ц")=1),1000,0) + IF(AND(L16="Ц",COUNTIF($L$3:$L$21,"Ц")=1),1000,0) + IF(AND(M16="Ц",COUNTIF($M$3:$M$21,"Ц")=1),1000,0) + IF(AND(N16="Ц",COUNTIF($N$3:$N$21,"Ц")=1),1000,0) + IF(AND(O16="Ц",COUNTIF($O$3:$O$21,"Ц")=1),1000,0) + IF(AND(P16="Ц",COUNTIF($P$3:$P$21,"Ц")=1),1000,0) + IF(AND(Q16="Ц",COUNTIF($Q$3:$Q$21,"Ц")=1),1000,0) + IF(AND(R16="Ц",COUNTIF($R$3:$R$21,"Ц")=1),1000,0) + IF(AND(S16="Ц",COUNTIF($S$3:$S$21,"Ц")=1),1000,0) + IF(AND(T16="Ц",COUNTIF($T$3:$T$21,"Ц")=1),1000,0) + IF(AND(U16="Ц",COUNTIF($U$3:$U$21,"Ц")=1),1000,0) + IF(AND(V16="Ц",COUNTIF($V$3:$V$21,"Ц")=1),1000,0) + IF(AND(W16="Ц",COUNTIF($W$3:$W$21,"Ц")=1),1000,0) + IF(AND(X16="Ц",COUNTIF($X$3:$X$21,"Ц")=1),1000,0) + IF(AND(Y16="Ц",COUNTIF($Y$3:$Y$21,"Ц")=1),1000,0) + IF(AND(Z16="Ц",COUNTIF($Z$3:$Z$21,"Ц")=1),1000,0) + IF(AND(AA16="Ц",COUNTIF($AA$3:$AA$21,"Ц")=1),1000,0) + IF(AND(AB16="Ц",COUNTIF($AB$3:$AB$21,"Ц")=1),1000,0) + IF(AND(AC16="Ц",COUNTIF($AC$3:$AC$21,"Ц")=1),1000,0) + IF(AND(AD16="Ц",COUNTIF($AD$3:$AD$21,"Ц")=1),1000,0) + IF(AND(AE16="Ц",COUNTIF($AE$3:$AE$21,"Ц")=1),1000,0) + IF(AND(AF16="Ц",COUNTIF($AF$3:$AF$21,"Ц")=1),1000,0) + IF(AND(AG16="Ц",COUNTIF($AG$3:$AG$21,"Ц")=1),1000,0) -> 0 | CE16: =SUM(AU16:CD16) -> 0 | CQ16: =(AU16+SUM(AY16:CD16))-SUM(CI16:CP16) -> 0 | CU16: =AJ16*AQ16-AH16*AQ16 -> 0
AO17: =AS17-AQ17 -> 0 | AQ17: =IF(AS17>15, AS17-15, 0) -> 0 | AS17: =COUNTIF(C17:AG17, "М")+COUNTIF(C17:AG17, "Ц")+COUNTIF(C17:AG17, "П")+COUNTIF(C17:AG17, "Ох")+COUNTIF(C17:AG17, "Оз")+COUNTIF(C17:AG17, "А")+COUNTIF(C17:AG17, "Р")+(COUNTIF(C17:AG17, "05М")/2)+(COUNTIF(C17:AG17, "05Ц")/2)+(COUNTIF(C17:AG17, "05П")/2)+(COUNTIF(C17:AG17, "05Ох")/2)+(COUNTIF(C17:AG17, "05Оз")/2)+(COUNTIF(C17:AG17, "05А")/2)+(COUNTIF(C17:AG17, "05Р")/2) -> 0 | AU17: =AO17*AH17+AQ17*AJ17 -> 0 | AY17: {=SUMPRODUCT( (RIGHT([1]Запрос1!$D$2:$D$43198,4)=RIGHT(A17,4))* ([1]Запрос1!$A$2:$A$43198>=$B$1)* ([1]Запрос1!$A$2:$A$43198<=$B$2)* [1]Запрос1!$F$2:$F$43198)*AL17} -> 0 | BC17: {=SUMPRODUCT( (RIGHT([2]Запрос1!$E$2:$E$2465,4) = RIGHT(A17,4)) * ([2]Запрос1!$A$2:$A$2465 >= $B$1) * ([2]Запрос1!$A$2:$A$2465 <= $B$2) * [2]Запрос1!$I$2:$I$2465 )*AM17} -> 0 | BG17: {=SUMPRODUCT( --(RIGHT([3]Запрос1!$C$2:$C$5232,4) = RIGHT(A17,4)), --([3]Запрос1!$E$2:$E$5232 >= $B$1), --([3]Запрос1!$E$2:$E$5232 <= $B$2) )*AN17} -> 0 | BK17: {=SUMPRODUCT( (RIGHT([4]Запрос1!$E$2:$E$5389,4)=RIGHT(A17,4))* ([4]Запрос1!$A$2:$A$5389>=$B$1)* ([4]Запрос1!$A$2:$A$5389<=$B$2)* [4]Запрос1!$J$2:$J$5389 )*0.01} -> 0 | BO17: 0 | BW17: =IF(AND(C17="Ц",COUNTIF($C$3:$C$21,"Ц")=1),1000,0) + IF(AND(D17="Ц",COUNTIF($D$3:$D$21,"Ц")=1),1000,0) + IF(AND(E17="Ц",COUNTIF($E$3:$E$21,"Ц")=1),1000,0) + IF(AND(F17="Ц",COUNTIF($F$3:$F$21,"Ц")=1),1000,0) + IF(AND(G17="Ц",COUNTIF($G$3:$G$21,"Ц")=1),1000,0) + IF(AND(H17="Ц",COUNTIF($H$3:$H$21,"Ц")=1),1000,0) + IF(AND(I17="Ц",COUNTIF($I$3:$I$21,"Ц")=1),1000,0) + IF(AND(J17="Ц",COUNTIF($J$3:$J$21,"Ц")=1),1000,0) + IF(AND(K17="Ц",COUNTIF($K$3:$K$21,"Ц")=1),1000,0) + IF(AND(L17="Ц",COUNTIF($L$3:$L$21,"Ц")=1),1000,0) + IF(AND(M17="Ц",COUNTIF($M$3:$M$21,"Ц")=1),1000,0) + IF(AND(N17="Ц",COUNTIF($N$3:$N$21,"Ц")=1),1000,0) + IF(AND(O17="Ц",COUNTIF($O$3:$O$21,"Ц")=1),1000,0) + IF(AND(P17="Ц",COUNTIF($P$3:$P$21,"Ц")=1),1000,0) + IF(AND(Q17="Ц",COUNTIF($Q$3:$Q$21,"Ц")=1),1000,0) + IF(AND(R17="Ц",COUNTIF($R$3:$R$21,"Ц")=1),1000,0) + IF(AND(S17="Ц",COUNTIF($S$3:$S$21,"Ц")=1),1000,0) + IF(AND(T17="Ц",COUNTIF($T$3:$T$21,"Ц")=1),1000,0) + IF(AND(U17="Ц",COUNTIF($U$3:$U$21,"Ц")=1),1000,0) + IF(AND(V17="Ц",COUNTIF($V$3:$V$21,"Ц")=1),1000,0) + IF(AND(W17="Ц",COUNTIF($W$3:$W$21,"Ц")=1),1000,0) + IF(AND(X17="Ц",COUNTIF($X$3:$X$21,"Ц")=1),1000,0) + IF(AND(Y17="Ц",COUNTIF($Y$3:$Y$21,"Ц")=1),1000,0) + IF(AND(Z17="Ц",COUNTIF($Z$3:$Z$21,"Ц")=1),1000,0) + IF(AND(AA17="Ц",COUNTIF($AA$3:$AA$21,"Ц")=1),1000,0) + IF(AND(AB17="Ц",COUNTIF($AB$3:$AB$21,"Ц")=1),1000,0) + IF(AND(AC17="Ц",COUNTIF($AC$3:$AC$21,"Ц")=1),1000,0) + IF(AND(AD17="Ц",COUNTIF($AD$3:$AD$21,"Ц")=1),1000,0) + IF(AND(AE17="Ц",COUNTIF($AE$3:$AE$21,"Ц")=1),1000,0) + IF(AND(AF17="Ц",COUNTIF($AF$3:$AF$21,"Ц")=1),1000,0) + IF(AND(AG17="Ц",COUNTIF($AG$3:$AG$21,"Ц")=1),1000,0) -> 0 | CE17: =SUM(AU17:CD17) -> 0 | CQ17: =(AU17+SUM(AY17:CD17))-SUM(CI17:CP17) -> 0 | CU17: =AJ17*AQ17-AH17*AQ17 -> 0
AO18: 0 | AQ18: 0 | AS18: 0 | AU18: =AO18*AH18+AQ18*AJ18 -> 0 | AY18: {=SUMPRODUCT( (RIGHT([1]Запрос1!$D$2:$D$43198,4)=RIGHT(A18,4))* ([1]Запрос1!$A$2:$A$43198>=$B$1)* ([1]Запрос1!$A$2:$A$43198<=$B$2)* [1]Запрос1!$F$2:$F$43198)*AL18} -> 0 | BC18: {=SUMPRODUCT( (RIGHT([2]Запрос1!$E$2:$E$2465,4) = RIGHT(A18,4)) * ([2]Запрос1!$A$2:$A$2465 >= $B$1) * ([2]Запрос1!$A$2:$A$2465 <= $B$2) * [2]Запрос1!$I$2:$I$2465 )*AM18} -> 0 | BG18: {=SUMPRODUCT( --(RIGHT([3]Запрос1!$C$2:$C$5232,4) = RIGHT(A18,4)), --([3]Запрос1!$E$2:$E$5232 >= $B$1), --([3]Запрос1!$E$2:$E$5232 <= $B$2) )*AN18} -> 0 | BK18: {=SUMPRODUCT( (RIGHT([4]Запрос1!$E$2:$E$5389,4)=RIGHT(A18,4))* ([4]Запрос1!$A$2:$A$5389>=$B$1)* ([4]Запрос1!$A$2:$A$5389<=$B$2)* [4]Запрос1!$J$2:$J$5389 )*0.01} -> 0 | BO18: {=SUMPRODUCT( (RIGHT([5]Запрос1!$E$2:$E$5270,4) = RIGHT(A18,4)) * ([5]Запрос1!$A$2:$A$5270 >= $B$1) * ([5]Запрос1!$A$2:$A$5270 <= $B$2) * [5]Запрос1!$I$2:$I$5270 )*0.25} -> 0 | BW18: =IF(AND(C18="Ц",COUNTIF($C$3:$C$21,"Ц")=1),1000,0) + IF(AND(D18="Ц",COUNTIF($D$3:$D$21,"Ц")=1),1000,0) + IF(AND(E18="Ц",COUNTIF($E$3:$E$21,"Ц")=1),1000,0) + IF(AND(F18="Ц",COUNTIF($F$3:$F$21,"Ц")=1),1000,0) + IF(AND(G18="Ц",COUNTIF($G$3:$G$21,"Ц")=1),1000,0) + IF(AND(H18="Ц",COUNTIF($H$3:$H$21,"Ц")=1),1000,0) + IF(AND(I18="Ц",COUNTIF($I$3:$I$21,"Ц")=1),1000,0) + IF(AND(J18="Ц",COUNTIF($J$3:$J$21,"Ц")=1),1000,0) + IF(AND(K18="Ц",COUNTIF($K$3:$K$21,"Ц")=1),1000,0) + IF(AND(L18="Ц",COUNTIF($L$3:$L$21,"Ц")=1),1000,0) + IF(AND(M18="Ц",COUNTIF($M$3:$M$21,"Ц")=1),1000,0) + IF(AND(N18="Ц",COUNTIF($N$3:$N$21,"Ц")=1),1000,0) + IF(AND(O18="Ц",COUNTIF($O$3:$O$21,"Ц")=1),1000,0) + IF(AND(P18="Ц",COUNTIF($P$3:$P$21,"Ц")=1),1000,0) + IF(AND(Q18="Ц",COUNTIF($Q$3:$Q$21,"Ц")=1),1000,0) + IF(AND(R18="Ц",COUNTIF($R$3:$R$21,"Ц")=1),1000,0) + IF(AND(S18="Ц",COUNTIF($S$3:$S$21,"Ц")=1),1000,0) + IF(AND(T18="Ц",COUNTIF($T$3:$T$21,"Ц")=1),1000,0) + IF(AND(U18="Ц",COUNTIF($U$3:$U$21,"Ц")=1),1000,0) + IF(AND(V18="Ц",COUNTIF($V$3:$V$21,"Ц")=1),1000,0) + IF(AND(W18="Ц",COUNTIF($W$3:$W$21,"Ц")=1),1000,0) + IF(AND(X18="Ц",COUNTIF($X$3:$X$21,"Ц")=1),1000,0) + IF(AND(Y18="Ц",COUNTIF($Y$3:$Y$21,"Ц")=1),1000,0) + IF(AND(Z18="Ц",COUNTIF($Z$3:$Z$21,"Ц")=1),1000,0) + IF(AND(AA18="Ц",COUNTIF($AA$3:$AA$21,"Ц")=1),1000,0) + IF(AND(AB18="Ц",COUNTIF($AB$3:$AB$21,"Ц")=1),1000,0) + IF(AND(AC18="Ц",COUNTIF($AC$3:$AC$21,"Ц")=1),1000,0) + IF(AND(AD18="Ц",COUNTIF($AD$3:$AD$21,"Ц")=1),1000,0) + IF(AND(AE18="Ц",COUNTIF($AE$3:$AE$21,"Ц")=1),1000,0) + IF(AND(AF18="Ц",COUNTIF($AF$3:$AF$21,"Ц")=1),1000,0) + IF(AND(AG18="Ц",COUNTIF($AG$3:$AG$21,"Ц")=1),1000,0) -> 0 | CE18: =SUM(AU18:CD18) -> 0 | CQ18: =(AU18+SUM(AY18:CD18))-SUM(CI18:CP18) -> 0
AO19: =AS19-AQ19 -> 0 | AQ19: =IF(AS19>15, AS19-15, 0) -> 0 | AS19: =COUNTIF(C19:AG19, "М")+COUNTIF(C19:AG19, "Ц")+COUNTIF(C19:AG19, "П")+COUNTIF(C19:AG19, "Ох")+COUNTIF(C19:AG19, "Оз")+COUNTIF(C19:AG19, "А")+COUNTIF(C19:AG19, "Р")+(COUNTIF(C19:AG19, "05М")/2)+(COUNTIF(C19:AG19, "05Ц")/2)+(COUNTIF(C19:AG19, "05П")/2)+(COUNTIF(C19:AG19, "05Ох")/2)+(COUNTIF(C19:AG19, "05Оз")/2)+(COUNTIF(C19:AG19, "05А")/2)+(COUNTIF(C19:AG19, "05Р")/2) -> 0 | AU19: =AO19*AH19+AQ19*AJ19 -> 0 | AY19: {=SUMPRODUCT( (RIGHT([1]Запрос1!$D$2:$D$43198,4)=RIGHT(A19,4))* ([1]Запрос1!$A$2:$A$43198>=$B$1)* ([1]Запрос1!$A$2:$A$43198<=$B$2)* [1]Запрос1!$F$2:$F$43198)*AL19} -> 0 | BC19: {=SUMPRODUCT( (RIGHT([2]Запрос1!$E$2:$E$2465,4) = RIGHT(A19,4)) * ([2]Запрос1!$A$2:$A$2465 >= $B$1) * ([2]Запрос1!$A$2:$A$2465 <= $B$2) * [2]Запрос1!$I$2:$I$2465 )*AM19} -> 0 | BG19: {=SUMPRODUCT( --(RIGHT([3]Запрос1!$C$2:$C$5232,4) = RIGHT(A19,4)), --([3]Запрос1!$E$2:$E$5232 >= $B$1), --([3]Запрос1!$E$2:$E$5232 <= $B$2) )*AN19} -> 0 | BK19: {=SUMPRODUCT( (RIGHT([4]Запрос1!$E$2:$E$5389,4)=RIGHT(A19,4))* ([4]Запрос1!$A$2:$A$5389>=$B$1)* ([4]Запрос1!$A$2:$A$5389<=$B$2)* [4]Запрос1!$J$2:$J$5389 )*0.01} -> 0 | BO19: {=SUMPRODUCT( (RIGHT([5]Запрос1!$E$2:$E$5270,4) = RIGHT(A19,4)) * ([5]Запрос1!$A$2:$A$5270 >= $B$1) * ([5]Запрос1!$A$2:$A$5270 <= $B$2) * [5]Запрос1!$I$2:$I$5270 )*0.25} -> 0 | BW19: =IF(AND(C19="Ц",COUNTIF($C$3:$C$21,"Ц")=1),1000,0) + IF(AND(D19="Ц",COUNTIF($D$3:$D$21,"Ц")=1),1000,0) + IF(AND(E19="Ц",COUNTIF($E$3:$E$21,"Ц")=1),1000,0) + IF(AND(F19="Ц",COUNTIF($F$3:$F$21,"Ц")=1),1000,0) + IF(AND(G19="Ц",COUNTIF($G$3:$G$21,"Ц")=1),1000,0) + IF(AND(H19="Ц",COUNTIF($H$3:$H$21,"Ц")=1),1000,0) + IF(AND(I19="Ц",COUNTIF($I$3:$I$21,"Ц")=1),1000,0) + IF(AND(J19="Ц",COUNTIF($J$3:$J$21,"Ц")=1),1000,0) + IF(AND(K19="Ц",COUNTIF($K$3:$K$21,"Ц")=1),1000,0) + IF(AND(L19="Ц",COUNTIF($L$3:$L$21,"Ц")=1),1000,0) + IF(AND(M19="Ц",COUNTIF($M$3:$M$21,"Ц")=1),1000,0) + IF(AND(N19="Ц",COUNTIF($N$3:$N$21,"Ц")=1),1000,0) + IF(AND(O19="Ц",COUNTIF($O$3:$O$21,"Ц")=1),1000,0) + IF(AND(P19="Ц",COUNTIF($P$3:$P$21,"Ц")=1),1000,0) + IF(AND(Q19="Ц",COUNTIF($Q$3:$Q$21,"Ц")=1),1000,0) + IF(AND(R19="Ц",COUNTIF($R$3:$R$21,"Ц")=1),1000,0) + IF(AND(S19="Ц",COUNTIF($S$3:$S$21,"Ц")=1),1000,0) + IF(AND(T19="Ц",COUNTIF($T$3:$T$21,"Ц")=1),1000,0) + IF(AND(U19="Ц",COUNTIF($U$3:$U$21,"Ц")=1),1000,0) + IF(AND(V19="Ц",COUNTIF($V$3:$V$21,"Ц")=1),1000,0) + IF(AND(W19="Ц",COUNTIF($W$3:$W$21,"Ц")=1),1000,0) + IF(AND(X19="Ц",COUNTIF($X$3:$X$21,"Ц")=1),1000,0) + IF(AND(Y19="Ц",COUNTIF($Y$3:$Y$21,"Ц")=1),1000,0) + IF(AND(Z19="Ц",COUNTIF($Z$3:$Z$21,"Ц")=1),1000,0) + IF(AND(AA19="Ц",COUNTIF($AA$3:$AA$21,"Ц")=1),1000,0) + IF(AND(AB19="Ц",COUNTIF($AB$3:$AB$21,"Ц")=1),1000,0) + IF(AND(AC19="Ц",COUNTIF($AC$3:$AC$21,"Ц")=1),1000,0) + IF(AND(AD19="Ц",COUNTIF($AD$3:$AD$21,"Ц")=1),1000,0) + IF(AND(AE19="Ц",COUNTIF($AE$3:$AE$21,"Ц")=1),1000,0) + IF(AND(AF19="Ц",COUNTIF($AF$3:$AF$21,"Ц")=1),1000,0) + IF(AND(AG19="Ц",COUNTIF($AG$3:$AG$21,"Ц")=1),1000,0) -> 0 | CE19: =SUM(AU19:CD19) -> 0 | CQ19: =(AU19+SUM(AY19:CD19))-SUM(CI19:CP19) -> 0 | CU19: =AJ19*AQ19-AH19*AQ19 -> 0
AO20: =AS20-AQ20 -> 0 | AQ20: =IF(AS20>15, AS20-15, 0) -> 0 | AS20: =COUNTIF(C20:AG20, "М")+COUNTIF(C20:AG20, "Ц")+COUNTIF(C20:AG20, "П")+COUNTIF(C20:AG20, "Ох")+COUNTIF(C20:AG20, "Оз")+COUNTIF(C20:AG20, "А")+COUNTIF(C20:AG20, "Р")+(COUNTIF(C20:AG20, "05М")/2)+(COUNTIF(C20:AG20, "05Ц")/2)+(COUNTIF(C20:AG20, "05П")/2)+(COUNTIF(C20:AG20, "05Ох")/2)+(COUNTIF(C20:AG20, "05Оз")/2)+(COUNTIF(C20:AG20, "05А")/2)+(COUNTIF(C20:AG20, "05Р")/2) -> 0 | AU20: =AO20*AH20+AQ20*AJ20 -> 0 | AY20: {=SUMPRODUCT( (RIGHT([1]Запрос1!$D$2:$D$43198,4)=RIGHT(A20,4))* ([1]Запрос1!$A$2:$A$43198>=$B$1)* ([1]Запрос1!$A$2:$A$43198<=$B$2)* [1]Запрос1!$F$2:$F$43198)*AL20} -> 0 | BC20: {=SUMPRODUCT( (RIGHT([2]Запрос1!$E$2:$E$2465,4) = RIGHT(A20,4)) * ([2]Запрос1!$A$2:$A$2465 >= $B$1) * ([2]Запрос1!$A$2:$A$2465 <= $B$2) * [2]Запрос1!$I$2:$I$2465 )*AM20} -> 0 | BG20: {=SUMPRODUCT( --(RIGHT([3]Запрос1!$C$2:$C$5232,4) = RIGHT(A20,4)), --([3]Запрос1!$E$2:$E$5232 >= $B$1), --([3]Запрос1!$E$2:$E$5232 <= $B$2) )*AN20} -> 0 | BK20: {=SUMPRODUCT( (RIGHT([4]Запрос1!$E$2:$E$5389,4)=RIGHT(A20,4))* ([4]Запрос1!$A$2:$A$5389>=$B$1)* ([4]Запрос1!$A$2:$A$5389<=$B$2)* [4]Запрос1!$J$2:$J$5389 )*0.01} -> 0 | BO20: {=SUMPRODUCT( (RIGHT([5]Запрос1!$E$2:$E$5270,4) = RIGHT(A20,4)) * ([5]Запрос1!$A$2:$A$5270 >= $B$1) * ([5]Запрос1!$A$2:$A$5270 <= $B$2) * [5]Запрос1!$I$2:$I$5270 )*0.25} -> 0 | BW20: =IF(AND(C20="Ц",COUNTIF($C$3:$C$21,"Ц")=1),1000,0) + IF(AND(D20="Ц",COUNTIF($D$3:$D$21,"Ц")=1),1000,0) + IF(AND(E20="Ц",COUNTIF($E$3:$E$21,"Ц")=1),1000,0) + IF(AND(F20="Ц",COUNTIF($F$3:$F$21,"Ц")=1),1000,0) + IF(AND(G20="Ц",COUNTIF($G$3:$G$21,"Ц")=1),1000,0) + IF(AND(H20="Ц",COUNTIF($H$3:$H$21,"Ц")=1),1000,0) + IF(AND(I20="Ц",COUNTIF($I$3:$I$21,"Ц")=1),1000,0) + IF(AND(J20="Ц",COUNTIF($J$3:$J$21,"Ц")=1),1000,0) + IF(AND(K20="Ц",COUNTIF($K$3:$K$21,"Ц")=1),1000,0) + IF(AND(L20="Ц",COUNTIF($L$3:$L$21,"Ц")=1),1000,0) + IF(AND(M20="Ц",COUNTIF($M$3:$M$21,"Ц")=1),1000,0) + IF(AND(N20="Ц",COUNTIF($N$3:$N$21,"Ц")=1),1000,0) + IF(AND(O20="Ц",COUNTIF($O$3:$O$21,"Ц")=1),1000,0) + IF(AND(P20="Ц",COUNTIF($P$3:$P$21,"Ц")=1),1000,0) + IF(AND(Q20="Ц",COUNTIF($Q$3:$Q$21,"Ц")=1),1000,0) + IF(AND(R20="Ц",COUNTIF($R$3:$R$21,"Ц")=1),1000,0) + IF(AND(S20="Ц",COUNTIF($S$3:$S$21,"Ц")=1),1000,0) + IF(AND(T20="Ц",COUNTIF($T$3:$T$21,"Ц")=1),1000,0) + IF(AND(U20="Ц",COUNTIF($U$3:$U$21,"Ц")=1),1000,0) + IF(AND(V20="Ц",COUNTIF($V$3:$V$21,"Ц")=1),1000,0) + IF(AND(W20="Ц",COUNTIF($W$3:$W$21,"Ц")=1),1000,0) + IF(AND(X20="Ц",COUNTIF($X$3:$X$21,"Ц")=1),1000,0) + IF(AND(Y20="Ц",COUNTIF($Y$3:$Y$21,"Ц")=1),1000,0) + IF(AND(Z20="Ц",COUNTIF($Z$3:$Z$21,"Ц")=1),1000,0) + IF(AND(AA20="Ц",COUNTIF($AA$3:$AA$21,"Ц")=1),1000,0) + IF(AND(AB20="Ц",COUNTIF($AB$3:$AB$21,"Ц")=1),1000,0) + IF(AND(AC20="Ц",COUNTIF($AC$3:$AC$21,"Ц")=1),1000,0) + IF(AND(AD20="Ц",COUNTIF($AD$3:$AD$21,"Ц")=1),1000,0) + IF(AND(AE20="Ц",COUNTIF($AE$3:$AE$21,"Ц")=1),1000,0) + IF(AND(AF20="Ц",COUNTIF($AF$3:$AF$21,"Ц")=1),1000,0) + IF(AND(AG20="Ц",COUNTIF($AG$3:$AG$21,"Ц")=1),1000,0) -> 0 | CE20: =SUM(AU20:CD20) -> 0 | CQ20: =(AU20+SUM(AY20:CD20))-SUM(CI20:CP20) -> 0 | CU20: =AJ20*AQ20-AH20*AQ20 -> 0
